Workbook

Sheet สมมติฐาน
A1: 🌞 Solar ROI Calculator — กรอกเฉพาะเซลล์สีเหลือง / ผลคำนวณอัตโนมัติสีฟ้า
A3: A. ระบบ Solar Panel
A4: ขนาดระบบ (kWp) | B4: 5 | C4: kWp
A5: ราคาติดตั้ง Solar (ไม่รวมแบต) | B5: 135000 | C5: บาท
A6: Performance Ratio | B6: 0.9 | C6: ทศนิยม เช่น 0.80 = 80%
A7: Peak Sun Hours ต่อวัน | B7: 4.5 | C7: ชม./วัน (ไทยเฉลี่ย 4.0–5.0)
A8: อัตราเสื่อมของแผง (%/ปี) | B8: 0.005 | C8: ทศนิยม เช่น 0.005 = 0.5%/ปี
A9: อายุระบบ (ปี) | B9: 25 | C9: ปี
A11: B. แบตเตอรี่ (ใส่ 0 = ไม่มีแบต)
A12: ความจุแบต (kWh) | B12: 10 | C12: kWh (ใส่ 0 ถ้าไม่ต้องการแบต)
A13: ราคาแบต | B13: 80000 | C13: บาท
A14: Depth of Discharge (DoD) | B14: 0.9 | C14: ทศนิยม ปกติ 0.80–0.90
A15: Round-trip Efficiency | B15: 0.92 | C15: ทศนิยม ปกติ 0.90–0.95
A16: อายุแบต (ปี) | B16: 10 | C16: ปี (LFP ~10–15 ปี)
A18: C. รูปแบบการใช้ไฟ
A19: ใช้ไฟรวมต่อเดือน | B19: 600 | C19: kWh/เดือน
A20: สัดส่วนใช้ไฟกลางวัน | B20: 0.4 | C20: ทศนิยม ช่วง ~08:00–17:00
A21: ราคาไฟซื้อจากการไฟฟ้า | B21: 4.5 | C21: บาท/หน่วย
A22: อัตราขึ้นค่าไฟต่อปี | B22: 0.03 | C22: ทศนิยม เช่น 0.03 = 3%/ปี
A24: D. Solar ภาคประชาชน — ราคารับซื้อ FiT
A25: ราคา FiT (ขายคืนรัฐ) | B25: 2.2 | C25: บาท/หน่วย (นโยบายปัจจุบัน 2.20 ฿)
A27: E. การเงิน
A28: ค่าบำรุงรักษาต่อปี | B28: 3500 | C28: บาท/ปี
A29: Discount Rate | B29: 0.05 | C29: ทศนิยม สำหรับ NPV
A31: F. Energy Flow/วัน (คำนวณอัตโนมัติ — ห้ามแก้ไข)
A32: พลังงาน Solar ผลิต/วัน (kWh) | B32: =B4*B7*B6 -> 20.25 | C32: kWh/วัน
A33: การใช้ไฟรวม/วัน | B33: =B19*12/365 -> 19.726027 | C33: kWh/วัน
A34: ใช้ไฟกลางวัน/วัน | B34: =B33*B20 -> 7.890411 | C34: kWh/วัน | D34: ช่วง 08:00-17:00
A35: ใช้ไฟกลางคืน/วัน | B35: =B33*(1-B20) -> 11.835616 | C35: kWh/วัน
A37: กรณี 1: ไม่มีแบต — Energy Flow/วัน
A38: ใช้เอง (Solar กลางวัน)/วัน | B38: =MIN(B32,B34) -> 7.890411 | C38: kWh/วัน | D38: ← MIN(ผลิต, กลางวัน)
A39: ขายคืน FiT/วัน | B39: =MAX(0,B32-B34) -> 12.359589 | C39: kWh/วัน | D39: ← MAX(0, ผลิต − กลางวัน) ไม่ติดลบ
A40: ซื้อจากกริด/วัน | B40: =B35+MAX(0,B34-B32) -> 11.835616 | C40: kWh/วัน | D40: ← กลางคืน + MAX(0, กลางวัน − ผลิต)
A42: กรณี 2: มีแบต — Energy Flow/วัน
A43: ส่วนเกินหลังใช้กลางวัน/วัน | B43: =MAX(0,B32-B34) -> 12.359589 | C43: kWh/วัน
A44: ชาร์จแบต/วัน | B44: =MIN(B43,B12*B14) -> 9 | C44: kWh/วัน | D44: ← MIN(ส่วนเกิน, ความจุ×DoD)
A45: ขายคืน FiT/วัน | B45: =MAX(0,B43-B12*B14) -> 3.359589 | C45: kWh/วัน | D45: ← MAX(0, ส่วนเกิน − ความจุแบต) ไม่ติดลบ
A46: แบตจ่ายกลางคืน/วัน | B46: =B44*B15 -> 8.28 | C46: kWh/วัน | D46: ← ชาร์จ × Round-trip Eff
A47: ซื้อกริดกลางคืน/วัน | B47: =MAX(0,B35-B46) -> 3.5556164 | C47: kWh/วัน | D47: ← MAX(0, กลางคืน − แบตจ่าย)
A48: ซื้อกริดรวม/วัน | B48: =MAX(0,B34-B32)+B47 -> 3.5556164 | C48: kWh/วัน
...

Sheet กระแสเงินสด
A1: กระแสเงินสด 25 ปี — เปรียบเทียบ 3 กรณี
B3: กรณี 1: Solar ไม่มีแบต | I3: กรณี 2: Solar + แบต | P3: Baseline (ไม่ติด Solar)
A4: ปี | B4: Solar (kWh/ปี) | C4: ใช้เอง (kWh) | D4: ขาย FiT (kWh) | E4: ประหยัด +FiT (฿) | F4: Net CF ปีนั้น (฿) | G4: Cumulative (฿) | I4: Solar (kWh/ปี) | J4: ใช้เอง (kWh) | K4: ขาย FiT (kWh) | L4: ประหยัด +FiT (฿) | M4: Net CF ปีนั้น (฿) | N4: Cumulative (฿) | P4: ค่าไฟ/ปี (฿) | Q4: Cum.ค่าไฟ (฿)
A5: 1 | B5: =สมมติฐาน!B32*(1-สมมติฐาน!B8)^(1-1)*365 -> 7391.25 | C5: =MIN(สมมติฐาน!B32*(1-สมมติฐาน!B8)^(1-1),สมมติฐาน!B34)*365 -> 2880 | D5: =MAX(0,สมมติฐาน!B32*(1-สมมติฐาน!B8)^(1-1)-สมมติฐาน!B34)*365 -> 4511.25 | E5: =(MIN(สมมติฐาน!B32*(1-สมมติฐาน!B8)^(1-1),สมมติฐาน!B34)*สมมติฐาน!B21*(1+สมมติฐาน!B22)^(1-1)+MAX(0,สมมติฐาน!B32*(1-สมมติฐาน!B8)^(1-1)-สมมติฐาน!B34)*สมมติฐาน!B25)*365 -> 22884.75 | F5: =E5-สมมติฐาน!B5-สมมติฐาน!B28 -> -115615.25 | G5: =F5 -> -115615.25 | I5: =สมมติฐาน!B32*(1-สมมติฐาน!B8)^(1-1)*365 -> 7391.25 | J5: =(MIN(สมมติฐาน!B32*(1-สมมติฐาน!B8)^(1-1),สมมติฐาน!B34)+MIN(สมมติฐาน!B35,(MIN(MAX(0,สมมติฐาน!B32*(1-สมมติฐาน!B8)^(1-1)-สมมติฐาน!B34),สมมติฐาน!B12*สมมติฐาน!B14))*สมมติฐาน!B15))*365 -> 5902.2 | K5: =MAX(0,MAX(0,สมมติฐาน!B32*(1-สมมติฐาน!B8)^(1-1)-สมมติฐาน!B34)-สมมติฐาน!B12*สมมติฐาน!B14)*365 -> 1226.25 | L5: =((MIN(สมมติฐาน!B32*(1-สมมติฐาน!B8)^(1-1),สมมติฐาน!B34)+MIN(สมมติฐาน!B35,(MIN(MAX(0,สมมติฐาน!B32*(1-สมมติฐาน!B8)^(1-1)-สมมติฐาน!B34),สมมติฐาน!B12*สมมติฐาน!B14))*สมมติฐาน!B15))*สมมติฐาน!B21*(1+สมมติฐาน!B22)^(1-1)+MAX(0,MAX(0,สมมติฐาน!B32*(1-สมมติฐาน!B8)^(1-1)-สมมติฐาน!B34)-สมมติฐาน!B12*สมมติฐาน!B14)*สมมติฐาน!B25)*365 -> 29257.65 | M5: =L5-สมมติฐาน!B5-สมมติฐาน!B13-สมมติฐาน!B28 -> -189242.35 | N5: =M5 -> -189242.35 | P5: =-สมมติฐาน!B33*365*สมมติฐาน!B21*(1+สมมติฐาน!B22)^(1-1) -> -32400 | Q5: =P5 -> -32400
A6: 2 | B6: =สมมติฐาน!B32*(1-สมมติฐาน!B8)^(2-1)*365 -> 7354.2937 | C6: =MIN(สมมติฐาน!B32*(1-สมมติฐาน!B8)^(2-1),สมมติฐาน!B34)*365 -> 2880 | D6: =MAX(0,สมมติฐาน!B32*(1-สมมติฐาน!B8)^(2-1)-สมมติฐาน!B34)*365 -> 4474.2937 | E6: =(MIN(สมมติฐาน!B32*(1-สมมติฐาน!B8)^(2-1),สมมติฐาน!B34)*สมมติฐาน!B21*(1+สมมติฐาน!B22)^(2-1)+MAX(0,สมมติฐาน!B32*(1-สมมติฐาน!B8)^(2-1)-สมมติฐาน!B34)*สมมติฐาน!B25)*365 -> 23192.246 | F6: =E6-สมมติฐาน!B28 -> 19692.246 | G6: =G5+F6 -> -95923.004 | I6: =สมมติฐาน!B32*(1-สมมติฐาน!B8)^(2-1)*365 -> 7354.2937 | J6: =(MIN(สมมติฐาน!B32*(1-สมมติฐาน!B8)^(2-1),สมมติฐาน!B34)+MIN(สมมติฐาน!B35,(MIN(MAX(0,สมมติฐาน!B32*(1-สมมติฐาน!B8)^(2-1)-สมมติฐาน!B34),สมมติฐาน!B12*สมมติฐาน!B14))*สมมติฐาน!B15))*365 -> 5902.2 | K6: =MAX(0,MAX(0,สมมติฐาน!B32*(1-สมมติฐาน!B8)^(2-1)-สมมติฐาน!B34)-สมมติฐาน!B12*สมมติฐาน!B14)*365 -> 1189.2938 | L6: =((MIN(สมมติฐาน!B32*(1-สมมติฐาน!B8)^(2-1),สมมติฐาน!B34)+MIN(สมมติฐาน!B35,(MIN(MAX(0,สมมติฐาน!B32*(1-สมมติฐาน!B8)^(2-1)-สมมติฐาน!B34),สมมติฐาน!B12*สมมติฐาน!B14))*สมมติฐาน!B15))*สมมติฐาน!B21*(1+สมมติฐาน!B22)^(2-1)+MAX(0,MAX(0,สมมติฐาน!B32*(1-สมมติฐาน!B8)^(2-1)-สมมติฐาน!B34)-สมมติฐาน!B12*สมมติฐาน!B14)*สมมติฐาน!B25)*365 -> 29973.143 | M6: =L6-สมมติฐาน!B28 -> 26473.143 | N6: =N5+M6 -> -162769.21 | P6: =-สมมติฐาน!B33*365*สมมติฐาน!B21*(1+สมมติฐาน!B22)^(2-1) -> -33372 | Q6: =Q5+P6 -> -65772
A7: 3 | B7: =สมมติฐาน!B32*(1-สมมติฐาน!B8)^(3-1)*365 -> 7317.5223 | C7: =MIN(สมมติฐาน!B32*(1-สมมติฐาน!B8)^(3-1),สมมติฐาน!B34)*365 -> 2880 | D7: =MAX(0,สมมติฐาน!B32*(1-สมมติฐาน!B8)^(3-1)-สมมติฐาน!B34)*365 -> 4437.5223 | E7: =(MIN(สมมติฐาน!B32*(1-สมมติฐาน!B8)^(3-1),สมมติฐาน!B34)*สมมติฐาน!B21*(1+สมมติฐาน!B22)^(3-1)+MAX(0,สมมติฐาน!B32*(1-สมมติฐาน!B8)^(3-1)-สมมติฐาน!B34)*สมมติฐาน!B25)*365 -> 23511.813 | F7: =E7-สมมติฐาน!B28 -> 20011.813 | G7: =G6+F7 -> -75911.191 | I7: =สมมติฐาน!B32*(1-สมมติฐาน!B8)^(3-1)*365 -> 7317.5223 | J7: =(MIN(สมมติฐาน!B32*(1-สมมติฐาน!B8)^(3-1),สมมติฐาน!B34)+MIN(สมมติฐาน!B35,(MIN(MAX(0,สมมติฐาน!B32*(1-สมมติฐาน!B8)^(3-1)-สมมติฐาน!B34),สมมติฐาน!B12*สมมติฐาน!B14))*สมมติฐาน!B15))*365 -> 5902.2 | K7: =MAX(0,MAX(0,สมมติฐาน!B32*(1-สมมติฐาน!B8)^(3-1)-สมมติฐาน!B34)-สมมติฐาน!B12*สมมติฐาน!B14)*365 -> 1152.5223 | L7: =((MIN(สมมติฐาน!B32*(1-สมมติฐาน!B8)^(3-1),สมมติฐาน!B34)+MIN(สมมติฐาน!B35,(MIN(MAX(0,สมมติฐาน!B32*(1-สมมติฐาน!B8)^(3-1)-สมมติฐาน!B34),สมมติฐาน!B12*สมมติฐาน!B14))*สมมติฐาน!B15))*สมมติฐาน!B21*(1+สมมติฐาน!B22)^(3-1)+MAX(0,MAX(0,สมมติฐาน!B32*(1-สมมติฐาน!B8)^(3-1)-สมมติฐาน!B34)-สมมติฐาน!B12*สมมติฐาน!B14)*สมมติฐาน!B25)*365 -> 30712.947 | M7: =L7-สมมติฐาน!B28 -> 27212.947 | N7: =N6+M7 -> -135556.26 | P7: =-สมมติฐาน!B33*365*สมมติฐาน!B21*(1+สมมติฐาน!B22)^(3-1) -> -34373.16 | Q7: =Q6+P7 -> -100145.16
A8: 4 | B8: =สมมติฐาน!B32*(1-สมมติฐาน!B8)^(4-1)*365 -> 7280.9347 | C8: =MIN(สมมติฐาน!B32*(1-สมมติฐาน!B8)^(4-1),สมมติฐาน!B34)*365 -> 2880 | D8: =MAX(0,สมมติฐาน!B32*(1-สมมติฐาน!B8)^(4-1)-สมมติฐาน!B34)*365 -> 4400.9347 | E8: =(MIN(สมมติฐาน!B32*(1-สมมติฐาน!B8)^(4-1),สมมติฐาน!B34)*สมมติฐาน!B21*(1+สมมติฐาน!B22)^(4-1)+MAX(0,สมมติฐาน!B32*(1-สมมติฐาน!B8)^(4-1)-สมมติฐาน!B34)*สมมติฐาน!B25)*365 -> 23843.798 | F8: =E8-สมมติฐาน!B28 -> 20343.798 | G8: =G7+F8 -> -55567.393 | I8: =สมมติฐาน!B32*(1-สมมติฐาน!B8)^(4-1)*365 -> 7280.9347 | J8: =(MIN(สมมติฐาน!B32*(1-สมมติฐาน!B8)^(4-1),สมมติฐาน!B34)+MIN(สมมติฐาน!B35,(MIN(MAX(0,สมมติฐาน!B32*(1-สมมติฐาน!B8)^(4-1)-สมมติฐาน!B34),สมมติฐาน!B12*สมมติฐาน!B14))*สมมติฐาน!B15))*365 -> 5902.2 | K8: =MAX(0,MAX(0,สมมติฐาน!B32*(1-สมมติฐาน!B8)^(4-1)-สมมติฐาน!B34)-สมมติฐาน!B12*สมมติฐาน!B14)*365 -> 1115.9347 | L8: =((MIN(สมมติฐาน!B32*(1-สมมติฐาน!B8)^(4-1),สมมติฐาน!B34)+MIN(สมมติฐาน!B35,(MIN(MAX(0,สมมติฐาน!B32*(1-สมมติฐาน!B8)^(4-1)-สมมติฐาน!B34),สมมติฐาน!B12*สมมติฐาน!B14))*สมมติฐาน!B15))*สมมติฐาน!B21*(1+สมมติฐาน!B22)^(4-1)+MAX(0,MAX(0,สมมติฐาน!B32*(1-สมมติฐาน!B8)^(4-1)-สมมติฐาน!B34)-สมมติฐาน!B12*สมมติฐาน!B14)*สมมติฐาน!B25)*365 -> 31477.776 | M8: =L8-สมมติฐาน!B28 -> 27977.776 | N8: =N7+M8 -> -107578.48 | P8: =-สมมติฐาน!B33*365*สมมติฐาน!B21*(1+สมมติฐาน!B22)^(4-1) -> -35404.355 | Q8: =Q7+P8 -> -135549.51
A9: 5 | B9: =สมมติฐาน!B32*(1-สมมติฐาน!B8)^(5-1)*365 -> 7244.53 | C9: =MIN(สมมติฐาน!B32*(1-สมมติฐาน!B8)^(5-1),สมมติฐาน!B34)*365 -> 2880 | D9: =MAX(0,สมมติฐาน!B32*(1-สมมติฐาน!B8)^(5-1)-สมมติฐาน!B34)*365 -> 4364.53 | E9: =(MIN(สมมติฐาน!B32*(1-สมมติฐาน!B8)^(5-1),สมมติฐาน!B34)*สมมติฐาน!B21*(1+สมมติฐาน!B22)^(5-1)+MAX(0,สมมติฐาน!B32*(1-สมมติฐาน!B8)^(5-1)-สมมติฐาน!B34)*สมมติฐาน!B25)*365 -> 24188.56 | F9: =E9-สมมติฐาน!B28 -> 20688.56 | G9: =G8+F9 -> -34878.832 | I9: =สมมติฐาน!B32*(1-สมมติฐาน!B8)^(5-1)*365 -> 7244.53 | J9: =(MIN(สมมติฐาน!B32*(1-สมมติฐาน!B8)^(5-1),สมมติฐาน!B34)+MIN(สมมติฐาน!B35,(MIN(MAX(0,สมมติฐาน!B32*(1-สมมติฐาน!B8)^(5-1)-สมมติฐาน!B34),สมมติฐาน!B12*สมมติฐาน!B14))*สมมติฐาน!B15))*365 -> 5902.2 | K9: =MAX(0,MAX(0,สมมติฐาน!B32*(1-สมมติฐาน!B8)^(5-1)-สมมติฐาน!B34)-สมมติฐาน!B12*สมมติฐาน!B14)*365 -> 1079.53 | L9: =((MIN(สมมติฐาน!B32*(1-สมมติฐาน!B8)^(5-1),สมมติฐาน!B34)+MIN(สมมติฐาน!B35,(MIN(MAX(0,สมมติฐาน!B32*(1-สมมติฐาน!B8)^(5-1)-สมมติฐาน!B34),สมมติฐาน!B12*สมมติฐาน!B14))*สมมติฐาน!B15))*สมมติฐาน!B21*(1+สมมติฐาน!B22)^(5-1)+MAX(0,MAX(0,สมมติฐาน!B32*(1-สมมติฐาน!B8)^(5-1)-สมมติฐาน!B34)-สมมติฐาน!B12*สมมติฐาน!B14)*สมมติฐาน!B25)*365 -> 32268.367 | M9: =L9-สมมติฐาน!B28 -> 28768.367 | N9: =N8+M9 -> -78810.116 | P9: =-สมมติฐาน!B33*365*สมมติฐาน!B21*(1+สมมติฐาน!B22)^(5-1) -> -36466.485 | Q9: =Q8+P9 -> -172016
A10: 6 | B10: =สมมติฐาน!B32*(1-สมมติฐาน!B8)^(6-1)*365 -> 7208.3073 | C10: =MIN(สมมติฐาน!B32*(1-สมมติฐาน!B8)^(6-1),สมมติฐาน!B34)*365 -> 2880 | D10: =MAX(0,สมมติฐาน!B32*(1-สมมติฐาน!B8)^(6-1)-สมมติฐาน!B34)*365 -> 4328.3073 | E10: =(MIN(สมมติฐาน!B32*(1-สมมติฐาน!B8)^(6-1),สมมติฐาน!B34)*สมมติฐาน!B21*(1+สมมติฐาน!B22)^(6-1)+MAX(0,สมมติฐาน!B32*(1-สมมติฐาน!B8)^(6-1)-สมมติฐาน!B34)*สมมติฐาน!B25)*365 -> 24546.468 | F10: =E10-สมมติฐาน!B28 -> 21046.468 | G10: =G9+F10 -> -13832.364 | I10: =สมมติฐาน!B32*(1-สมมติฐาน!B8)^(6-1)*365 -> 7208.3073 | J10: =(MIN(สมมติฐาน!B32*(1-สมมติฐาน!B8)^(6-1),สมมติฐาน!B34)+MIN(สมมติฐาน!B35,(MIN(MAX(0,สมมติฐาน!B32*(1-สมมติฐาน!B8)^(6-1)-สมมติฐาน!B34),สมมติฐาน!B12*สมมติฐาน!B14))*สมมติฐาน!B15))*365 -> 5902.2 | K10: =MAX(0,MAX(0,สมมติฐาน!B32*(1-สมมติฐาน!B8)^(6-1)-สมมติฐาน!B34)-สมมติฐาน!B12*สมมติฐาน!B14)*365 -> 1043.3073 | L10: =((MIN(สมมติฐาน!B32*(1-สมมติฐาน!B8)^(6-1),สมมติฐาน!B34)+MIN(สมมติฐาน!B35,(MIN(MAX(0,สมมติฐาน!B32*(1-สมมติฐาน!B8)^(6-1)-สมมติฐาน!B34),สมมติฐาน!B12*สมมติฐาน!B14))*สมมติฐาน!B15))*สมมติฐาน!B21*(1+สมมติฐาน!B22)^(6-1)+MAX(0,MAX(0,สมมติฐาน!B32*(1-สมมติฐาน!B8)^(6-1)-สมมติฐาน!B34)-สมมติฐาน!B12*สมมติฐาน!B14)*สมมติฐาน!B25)*365 -> 33085.48 | M10: =L10-สมมติฐาน!B28 -> 29585.48 | N10: =N9+M10 -> -49224.637 | P10: =-สมมติฐาน!B33*365*สมมติฐาน!B21*(1+สมมติฐาน!B22)^(6-1) -> -37560.48 | Q10: =Q9+P10 -> -209576.48
A11: 7 | B11: =สมมติฐาน!B32*(1-สมมติฐาน!B8)^(7-1)*365 -> 7172.2658 | C11: =MIN(สมมติฐาน!B32*(1-สมมติฐาน!B8)^(7-1),สมมติฐาน!B34)*365 -> 2880 | D11: =MAX(0,สมมติฐาน!B32*(1-สมมติฐาน!B8)^(7-1)-สมมติฐาน!B34)*365 -> 4292.2658 | E11: =(MIN(สมมติฐาน!B32*(1-สมมติฐาน!B8)^(7-1),สมมติฐาน!B34)*สมมติฐาน!B21*(1+สมมติฐาน!B22)^(7-1)+MAX(0,สมมติฐาน!B32*(1-สมมติฐาน!B8)^(7-1)-สมมติฐาน!B34)*สมมติฐาน!B25)*365 -> 24917.903 | F11: =E11-สมมติฐาน!B28 -> 21417.903 | G11: =G10+F11 -> 7585.5383 | I11: =สมมติฐาน!B32*(1-สมมติฐาน!B8)^(7-1)*365 -> 7172.2658 | J11: =(MIN(สมมติฐาน!B32*(1-สมมติฐาน!B8)^(7-1),สมมติฐาน!B34)+MIN(สมมติฐาน!B35,(MIN(MAX(0,สมมติฐาน!B32*(1-สมมติฐาน!B8)^(7-1)-สมมติฐาน!B34),สมมติฐาน!B12*สมมติฐาน!B14))*สมมติฐาน!B15))*365 -> 5902.2 | K11: =MAX(0,MAX(0,สมมติฐาน!B32*(1-สมมติฐาน!B8)^(7-1)-สมมติฐาน!B34)-สมมติฐาน!B12*สมมติฐาน!B14)*365 -> 1007.2658 | L11: =((MIN(สมมติฐาน!B32*(1-สมมติฐาน!B8)^(7-1),สมมติฐาน!B34)+MIN(สมมติฐาน!B35,(MIN(MAX(0,สมมติฐาน!B32*(1-สมมติฐาน!B8)^(7-1)-สมมติฐาน!B34),สมมติฐาน!B12*สมมติฐาน!B14))*สมมติฐาน!B15))*สมมติฐาน!B21*(1+สมมติฐาน!B22)^(7-1)+MAX(0,MAX(0,สมมติฐาน!B32*(1-สมมติฐาน!B8)^(7-1)-สมมติฐาน!B34)-สมมติฐาน!B12*สมมติฐาน!B14)*สมมติฐาน!B25)*365 -> 33929.894 | M11: =L11-สมมติฐาน!B28 -> 30429.894 | N11: =N10+M11 -> -18794.742 | P11: =-สมมติฐาน!B33*365*สมมติฐาน!B21*(1+สมมติฐาน!B22)^(7-1) -> -38687.294 | Q11: =Q10+P11 -> -248263.77
A12: 8 | B12: =สมมติฐาน!B32*(1-สมมติฐาน!B8)^(8-1)*365 -> 7136.4045 | C12: =MIN(สมมติฐาน!B32*(1-สมมติฐาน!B8)^(8-1),สมมติฐาน!B34)*365 -> 2880 | D12: =MAX(0,สมมติฐาน!B32*(1-สมมติฐาน!B8)^(8-1)-สมมติฐาน!B34)*365 -> 4256.4045 | E12: =(MIN(สมมติฐาน!B32*(1-สมมติฐาน!B8)^(8-1),สมมติฐาน!B34)*สมมติฐาน!B21*(1+สมมติฐาน!B22)^(8-1)+MAX(0,สมมติฐาน!B32*(1-สมมติฐาน!B8)^(8-1)-สมมติฐาน!B34)*สมมติฐาน!B25)*365 -> 25303.255 | F12: =E12-สมมติฐาน!B28 -> 21803.255 | G12: =G11+F12 -> 29388.793 | I12: =สมมติฐาน!B32*(1-สมมติฐาน!B8)^(8-1)*365 -> 7136.4045 | J12: =(MIN(สมมติฐาน!B32*(1-สมมติฐาน!B8)^(8-1),สมมติฐาน!B34)+MIN(สมมติฐาน!B35,(MIN(MAX(0,สมมติฐาน!B32*(1-สมมติฐาน!B8)^(8-1)-สมมติฐาน!B34),สมมติฐาน!B12*สมมติฐาน!B14))*สมมติฐาน!B15))*365 -> 5902.2 | K12: =MAX(0,MAX(0,สมมติฐาน!B32*(1-สมมติฐาน!B8)^(8-1)-สมมติฐาน!B34)-สมมติฐาน!B12*สมมติฐาน!B14)*365 -> 971.40448 | L12: =((MIN(สมมติฐาน!B32*(1-สมมติฐาน!B8)^(8-1),สมมติฐาน!B34)+MIN(สมมติฐาน!B35,(MIN(MAX(0,สมมติฐาน!B32*(1-สมมติฐาน!B8)^(8-1)-สมมติฐาน!B34),สมมติฐาน!B12*สมมติฐาน!B14))*สมมติฐาน!B15))*สมมติฐาน!B21*(1+สมมติฐาน!B22)^(8-1)+MAX(0,MAX(0,สมมติฐาน!B32*(1-สมมติฐาน!B8)^(8-1)-สมมติฐาน!B34)-สมมติฐาน!B12*สมมติฐาน!B14)*สมมติฐาน!B25)*365 -> 34802.417 | M12: =L12-สมมติฐาน!B28 -> 31302.417 | N12: =N11+M12 -> 12507.674 | P12: =-สมมติฐาน!B33*365*สมมติฐาน!B21*(1+สมมติฐาน!B22)^(8-1) -> -39847.913 | Q12: =Q11+P12 -> -288111.69
A13: 9 | B13: =สมมติฐาน!B32*(1-สมมติฐาน!B8)^(9-1)*365 -> 7100.7225 | C13: =MIN(สมมติฐาน!B32*(1-สมมติฐาน!B8)^(9-1),สมมติฐาน!B34)*365 -> 2880 | D13: =MAX(0,สมมติฐาน!B32*(1-สมมติฐาน!B8)^(9-1)-สมมติฐาน!B34)*365 -> 4220.7225 | E13: =(MIN(สมมติฐาน!B32*(1-สมมติฐาน!B8)^(9-1),สมมติฐาน!B34)*สมมติฐาน!B21*(1+สมมติฐาน!B22)^(9-1)+MAX(0,สมมติฐาน!B32*(1-สมมติฐาน!B8)^(9-1)-สมมติฐาน!B34)*สมมติฐาน!B25)*365 -> 25702.93 | F13: =E13-สมมติฐาน!B28 -> 22202.93 | G13: =G12+F13 -> 51591.723 | I13: =สมมติฐาน!B32*(1-สมมติฐาน!B8)^(9-1)*365 -> 7100.7225 | J13: =(MIN(สมมติฐาน!B32*(1-สมมติฐาน!B8)^(9-1),สมมติฐาน!B34)+MIN(สมมติฐาน!B35,(MIN(MAX(0,สมมติฐาน!B32*(1-สมมติฐาน!B8)^(9-1)-สมมติฐาน!B34),สมมติฐาน!B12*สมมติฐาน!B14))*สมมติฐาน!B15))*365 -> 5902.2 | K13: =MAX(0,MAX(0,สมมติฐาน!B32*(1-สมมติฐาน!B8)^(9-1)-สมมติฐาน!B34)-สมมติฐาน!B12*สมมติฐาน!B14)*365 -> 935.72246 | L13: =((MIN(สมมติฐาน!B32*(1-สมมติฐาน!B8)^(9-1),สมมติฐาน!B34)+MIN(สมมติฐาน!B35,(MIN(MAX(0,สมมติฐาน!B32*(1-สมมติฐาน!B8)^(9-1)-สมมติฐาน!B34),สมมติฐาน!B12*สมมติฐาน!B14))*สมมติฐาน!B15))*สมมติฐาน!B21*(1+สมมติฐาน!B22)^(9-1)+MAX(0,MAX(0,สมมติฐาน!B32*(1-สมมติฐาน!B8)^(9-1)-สมมติฐาน!B34)-สมมติฐาน!B12*สมมติฐาน!B14)*สมมติฐาน!B25)*365 -> 35703.876 | M13: =L13-สมมติฐาน!B28 -> 32203.876 | N13: =N12+M13 -> 44711.551 | P13: =-สมมติฐาน!B33*365*สมมติฐาน!B21*(1+สมมติฐาน!B22)^(9-1) -> -41043.351 | Q13: =Q12+P13 -> -329155.04
A14: 10 | B14: =สมมติฐาน!B32*(1-สมมติฐาน!B8)^(10-1)*365 -> 7065.2188 | C14: =MIN(สมมติฐาน!B32*(1-สมมติฐาน!B8)^(10-1),สมมติฐาน!B34)*365 -> 2880 | D14: =MAX(0,สมมติฐาน!B32*(1-สมมติฐาน!B8)^(10-1)-สมมติฐาน!B34)*365 -> 4185.2188 | E14: =(MIN(สมมติฐาน!B32*(1-สมมติฐาน!B8)^(10-1),สมมติฐาน!B34)*สมมติฐาน!B21*(1+สมมติฐาน!B22)^(10-1)+MAX(0,สมมติฐาน!B32*(1-สมมติฐาน!B8)^(10-1)-สมมติฐาน!B34)*สมมติฐาน!B25)*365 -> 26117.342 | F14: =E14-สมมติฐาน!B28 -> 22617.342 | G14: =G13+F14 -> 74209.065 | I14: =สมมติฐาน!B32*(1-สมมติฐาน!B8)^(10-1)*365 -> 7065.2188 | J14: =(MIN(สมมติฐาน!B32*(1-สมมติฐาน!B8)^(10-1),สมมติฐาน!B34)+MIN(สมมติฐาน!B35,(MIN(MAX(0,สมมติฐาน!B32*(1-สมมติฐาน!B8)^(10-1)-สมมติฐาน!B34),สมมติฐาน!B12*สมมติฐาน!B14))*สมมติฐาน!B15))*365 -> 5902.2 | K14: =MAX(0,MAX(0,สมมติฐาน!B32*(1-สมมติฐาน!B8)^(10-1)-สมมติฐาน!B34)-สมมติฐาน!B12*สมมติฐาน!B14)*365 -> 900.21885 | L14: =((MIN(สมมติฐาน!B32*(1-สมมติฐาน!B8)^(10-1),สมมติฐาน!B34)+MIN(สมมติฐาน!B35,(MIN(MAX(0,สมมติฐาน!B32*(1-สมมติฐาน!B8)^(10-1)-สมมติฐาน!B34),สมมติฐาน!B12*สมมติฐาน!B14))*สมมติฐาน!B15))*สมมติฐาน!B21*(1+สมมติฐาน!B22)^(10-1)+MAX(0,MAX(0,สมมติฐาน!B32*(1-สมมติฐาน!B8)^(10-1)-สมมติฐาน!B34)-สมมติฐาน!B12*สมมติฐาน!B14)*สมมติฐาน!B25)*365 -> 36635.127 | M14: =L14-สมมติฐาน!B28 -> 33135.127 | N14: =N13+M14 -> 77846.677 | P14: =-สมมติฐาน!B33*365*สมมติฐาน!B21*(1+สมมติฐาน!B22)^(10-1) -> -42274.651 | Q14: =Q13+P14 -> -371429.69
A15: 11 | B15: =สมมติฐาน!B32*(1-สมมติฐาน!B8)^(11-1)*365 -> 7029.8928 | C15: =MIN(สมมติฐาน!B32*(1-สมมติฐาน!B8)^(11-1),สมมติฐาน!B34)*365 -> 2880 | D15: =MAX(0,สมมติฐาน!B32*(1-สมมติฐาน!B8)^(11-1)-สมมติฐาน!B34)*365 -> 4149.8928 | E15: =(MIN(สมมติฐาน!B32*(1-สมมติฐาน!B8)^(11-1),สมมติฐาน!B34)*สมมติฐาน!B21*(1+สมมติฐาน!B22)^(11-1)+MAX(0,สมมติฐาน!B32*(1-สมมติฐาน!B8)^(11-1)-สมมติฐาน!B34)*สมมติฐาน!B25)*365 -> 26546.92 | F15: =E15-สมมติฐาน!B28 -> 23046.92 | G15: =G14+F15 -> 97255.985 | I15: =สมมติฐาน!B32*(1-สมมติฐาน!B8)^(11-1)*365 -> 7029.8928 | J15: =(MIN(สมมติฐาน!B32*(1-สมมติฐาน!B8)^(11-1),สมมติฐาน!B34)+MIN(สมมติฐาน!B35,(MIN(MAX(0,สมมติฐาน!B32*(1-สมมติฐาน!B8)^(11-1)-สมมติฐาน!B34),สมมติฐาน!B12*สมมติฐาน!B14))*สมมติฐาน!B15))*365 -> 5902.2 | K15: =MAX(0,MAX(0,สมมติฐาน!B32*(1-สมมติฐาน!B8)^(11-1)-สมมติฐาน!B34)-สมมติฐาน!B12*สมมติฐาน!B14)*365 -> 864.89275 | L15: =((MIN(สมมติฐาน!B32*(1-สมมติฐาน!B8)^(11-1),สมมติฐาน!B34)+MIN(สมมติฐาน!B35,(MIN(MAX(0,สมมติฐาน!B32*(1-สมมติฐาน!B8)^(11-1)-สมมติฐาน!B34),สมมติฐาน!B12*สมมติฐาน!B14))*สมมติฐาน!B15))*สมมติฐาน!B21*(1+สมมติฐาน!B22)^(11-1)+MAX(0,MAX(0,สมมติฐาน!B32*(1-สมมติฐาน!B8)^(11-1)-สมมติฐาน!B34)-สมมติฐาน!B12*สมมติฐาน!B14)*สมมติฐาน!B25)*365 -> 37597.049 | M15: =L15-สมมติฐาน!B28-สมมติฐาน!B13 -> -45902.951 | N15: =N14+M15 -> 31943.726 | P15: =-สมมติฐาน!B33*365*สมมติฐาน!B21*(1+สมมติฐาน!B22)^(11-1) -> -43542.891 | Q15: =Q14+P15 -> -414972.58
A16: 12 | B16: =สมมติฐาน!B32*(1-สมมติฐาน!B8)^(12-1)*365 -> 6994.7433 | C16: =MIN(สมมติฐาน!B32*(1-สมมติฐาน!B8)^(12-1),สมมติฐาน!B34)*365 -> 2880 | D16: =MAX(0,สมมติฐาน!B32*(1-สมมติฐาน!B8)^(12-1)-สมมติฐาน!B34)*365 -> 4114.7433 | E16: =(MIN(สมมติฐาน!B32*(1-สมมติฐาน!B8)^(12-1),สมมติฐาน!B34)*สมมติฐาน!B21*(1+สมมติฐาน!B22)^(12-1)+MAX(0,สมมติฐาน!B32*(1-สมมติฐาน!B8)^(12-1)-สมมติฐาน!B34)*สมมติฐาน!B25)*365 -> 26992.106 | F16: =E16-สมมติฐาน!B28 -> 23492.106 | G16: =G15+F16 -> 120748.09 | I16: =สมมติฐาน!B32*(1-สมมติฐาน!B8)^(12-1)*365 -> 6994.7433 | J16: =(MIN(สมมติฐาน!B32*(1-สมมติฐาน!B8)^(12-1),สมมติฐาน!B34)+MIN(สมมติฐาน!B35,(MIN(MAX(0,สมมติฐาน!B32*(1-สมมติฐาน!B8)^(12-1)-สมมติฐาน!B34),สมมติฐาน!B12*สมมติฐาน!B14))*สมมติฐาน!B15))*365 -> 5902.2 | K16: =MAX(0,MAX(0,สมมติฐาน!B32*(1-สมมติฐาน!B8)^(12-1)-สมมติฐาน!B34)-สมมติฐาน!B12*สมมติฐาน!B14)*365 -> 829.74329 | L16: =((MIN(สมมติฐาน!B32*(1-สมมติฐาน!B8)^(12-1),สมมติฐาน!B34)+MIN(สมมติฐาน!B35,(MIN(MAX(0,สมมติฐาน!B32*(1-สมมติฐาน!B8)^(12-1)-สมมติฐาน!B34),สมมติฐาน!B12*สมมติฐาน!B14))*สมมติฐาน!B15))*สมมติฐาน!B21*(1+สมมติฐาน!B22)^(12-1)+MAX(0,MAX(0,สมมติฐาน!B32*(1-สมมติฐาน!B8)^(12-1)-สมมติฐาน!B34)-สมมติฐาน!B12*สมมติฐาน!B14)*สมมติฐาน!B25)*365 -> 38590.548 | M16: =L16-สมมติฐาน!B28 -> 35090.548 | N16: =N15+M16 -> 67034.274 | P16: =-สมมติฐาน!B33*365*สมมติฐาน!B21*(1+สมมติฐาน!B22)^(12-1) -> -44849.177 | Q16: =Q15+P16 -> -459821.76
A17: 13 | B17: =สมมติฐาน!B32*(1-สมมติฐาน!B8)^(13-1)*365 -> 6959.7696 | C17: =MIN(สมมติฐาน!B32*(1-สมมติฐาน!B8)^(13-1),สมมติฐาน!B34)*365 -> 2880 | D17: =MAX(0,สมมติฐาน!B32*(1-สมมติฐาน!B8)^(13-1)-สมมติฐาน!B34)*365 -> 4079.7696 | E17: =(MIN(สมมติฐาน!B32*(1-สมมติฐาน!B8)^(13-1),สมมติฐาน!B34)*สมมติฐาน!B21*(1+สมมติฐาน!B22)^(13-1)+MAX(0,สมมติฐาน!B32*(1-สมมติฐาน!B8)^(13-1)-สมมติฐาน!B34)*สมมติฐาน!B25)*365 -> 27453.354 | F17: =E17-สมมติฐาน!B28 -> 23953.354 | G17: =G16+F17 -> 144701.45 | I17: =สมมติฐาน!B32*(1-สมมติฐาน!B8)^(13-1)*365 -> 6959.7696 | J17: =(MIN(สมมติฐาน!B32*(1-สมมติฐาน!B8)^(13-1),สมมติฐาน!B34)+MIN(สมมติฐาน!B35,(MIN(MAX(0,สมมติฐาน!B32*(1-สมมติฐาน!B8)^(13-1)-สมมติฐาน!B34),สมมติฐาน!B12*สมมติฐาน!B14))*สมมติฐาน!B15))*365 -> 5902.2 | K17: =MAX(0,MAX(0,สมมติฐาน!B32*(1-สมมติฐาน!B8)^(13-1)-สมมติฐาน!B34)-สมมติฐาน!B12*สมมติฐาน!B14)*365 -> 794.76957 | L17: =((MIN(สมมติฐาน!B32*(1-สมมติฐาน!B8)^(13-1),สมมติฐาน!B34)+MIN(สมมติฐาน!B35,(MIN(MAX(0,สมมติฐาน!B32*(1-สมมติฐาน!B8)^(13-1)-สมมติฐาน!B34),สมมติฐาน!B12*สมมติฐาน!B14))*สมมติฐาน!B15))*สมมติฐาน!B21*(1+สมมติฐาน!B22)^(13-1)+MAX(0,MAX(0,สมมติฐาน!B32*(1-สมมติฐาน!B8)^(13-1)-สมมติฐาน!B34)-สมมติฐาน!B12*สมมติฐาน!B14)*สมมติฐาน!B25)*365 -> 39616.56 | M17: =L17-สมมติฐาน!B28 -> 36116.56 | N17: =N16+M17 -> 103150.83 | P17: =-สมมติฐาน!B33*365*สมมติฐาน!B21*(1+สมมติฐาน!B22)^(13-1) -> -46194.653 | Q17: =Q16+P17 -> -506016.41
A18: 14 | B18: =สมมติฐาน!B32*(1-สมมติฐาน!B8)^(14-1)*365 -> 6924.9707 | C18: =MIN(สมมติฐาน!B32*(1-สมมติฐาน!B8)^(14-1),สมมติฐาน!B34)*365 -> 2880 | D18: =MAX(0,สมมติฐาน!B32*(1-สมมติฐาน!B8)^(14-1)-สมมติฐาน!B34)*365 -> 4044.9707 | E18: =(MIN(สมมติฐาน!B32*(1-สมมติฐาน!B8)^(14-1),สมมติฐาน!B34)*สมมติฐาน!B21*(1+สมมติฐาน!B22)^(14-1)+MAX(0,สมมติฐาน!B32*(1-สมมติฐาน!B8)^(14-1)-สมมติฐาน!B34)*สมมติฐาน!B25)*365 -> 27931.133 | F18: =E18-สมมติฐาน!B28 -> 24431.133 | G18: =G17+F18 -> 169132.58 | I18: =สมมติฐาน!B32*(1-สมมติฐาน!B8)^(14-1)*365 -> 6924.9707 | J18: =(MIN(สมมติฐาน!B32*(1-สมมติฐาน!B8)^(14-1),สมมติฐาน!B34)+MIN(สมมติฐาน!B35,(MIN(MAX(0,สมมติฐาน!B32*(1-สมมติฐาน!B8)^(14-1)-สมมติฐาน!B34),สมมติฐาน!B12*สมมติฐาน!B14))*สมมติฐาน!B15))*365 -> 5902.2 | K18: =MAX(0,MAX(0,สมมติฐาน!B32*(1-สมมติฐาน!B8)^(14-1)-สมมติฐาน!B34)-สมมติฐาน!B12*สมมติฐาน!B14)*365 -> 759.97072 | L18: =((MIN(สมมติฐาน!B32*(1-สมมติฐาน!B8)^(14-1),สมมติฐาน!B34)+MIN(สมมติฐาน!B35,(MIN(MAX(0,สมมติฐาน!B32*(1-สมมติฐาน!B8)^(14-1)-สมมติฐาน!B34),สมมติฐาน!B12*สมมติฐาน!B14))*สมมติฐาน!B15))*สมมติฐาน!B21*(1+สมมติฐาน!B22)^(14-1)+MAX(0,MAX(0,สมมติฐาน!B32*(1-สมมติฐาน!B8)^(14-1)-สมมติฐาน!B34)-สมมติฐาน!B12*สมมติฐาน!B14)*สมมติฐาน!B25)*365 -> 40676.044 | M18: =L18-สมมติฐาน!B28 -> 37176.044 | N18: =N17+M18 -> 140326.88 | P18: =-สมมติฐาน!B33*365*สมมติฐาน!B21*(1+สมมติฐาน!B22)^(14-1) -> -47580.492 | Q18: =Q17+P18 -> -553596.9
A19: 15 | B19: =สมมติฐาน!B32*(1-สมมติฐาน!B8)^(15-1)*365 -> 6890.3459 | C19: =MIN(สมมติฐาน!B32*(1-สมมติฐาน!B8)^(15-1),สมมติฐาน!B34)*365 -> 2880 | D19: =MAX(0,สมมติฐาน!B32*(1-สมมติฐาน!B8)^(15-1)-สมมติฐาน!B34)*365 -> 4010.3459 | E19: =(MIN(สมมติฐาน!B32*(1-สมมติฐาน!B8)^(15-1),สมมติฐาน!B34)*สมมติฐาน!B21*(1+สมมติฐาน!B22)^(15-1)+MAX(0,สมมติฐาน!B32*(1-สมมติฐาน!B8)^(15-1)-สมมติฐาน!B34)*สมมติฐาน!B25)*365 -> 28425.924 | F19: =E19-สมมติฐาน!B28 -> 24925.924 | G19: =G18+F19 -> 194058.5 | I19: =สมมติฐาน!B32*(1-สมมติฐาน!B8)^(15-1)*365 -> 6890.3459 | J19: =(MIN(สมมติฐาน!B32*(1-สมมติฐาน!B8)^(15-1),สมมติฐาน!B34)+MIN(สมมติฐาน!B35,(MIN(MAX(0,สมมติฐาน!B32*(1-สมมติฐาน!B8)^(15-1)-สมมติฐาน!B34),สมมติฐาน!B12*สมมติฐาน!B14))*สมมติฐาน!B15))*365 -> 5902.2 | K19: =MAX(0,MAX(0,สมมติฐาน!B32*(1-สมมติฐาน!B8)^(15-1)-สมมติฐาน!B34)-สมมติฐาน!B12*สมมติฐาน!B14)*365 -> 725.34587 | L19: =((MIN(สมมติฐาน!B32*(1-สมมติฐาน!B8)^(15-1),สมมติฐาน!B34)+MIN(สมมติฐาน!B35,(MIN(MAX(0,สมมติฐาน!B32*(1-สมมติฐาน!B8)^(15-1)-สมมติฐาน!B34),สมมติฐาน!B12*สมมติฐาน!B14))*สมมติฐาน!B15))*สมมติฐาน!B21*(1+สมมติฐาน!B22)^(15-1)+MAX(0,MAX(0,สมมติฐาน!B32*(1-สมมติฐาน!B8)^(15-1)-สมมติฐาน!B34)-สมมติฐาน!B12*สมมติฐาน!B14)*สมมติฐาน!B25)*365 -> 41769.993 | M19: =L19-สมมติฐาน!B28 -> 38269.993 | N19: =N18+M19 -> 178596.87 | P19: =-สมมติฐาน!B33*365*สมมติฐาน!B21*(1+สมมติฐาน!B22)^(15-1) -> -49007.907 | Q19: =Q18+P19 -> -602604.81
A20: 16 | B20: =สมมติฐาน!B32*(1-สมมติฐาน!B8)^(16-1)*365 -> 6855.8941 | C20: =MIN(สมมติฐาน!B32*(1-สมมติฐาน!B8)^(16-1),สมมติฐาน!B34)*365 -> 2880 | D20: =MAX(0,สมมติฐาน!B32*(1-สมมติฐาน!B8)^(16-1)-สมมติฐาน!B34)*365 -> 3975.8941 | E20: =(MIN(สมมติฐาน!B32*(1-สมมติฐาน!B8)^(16-1),สมมติฐาน!B34)*สมมติฐาน!B21*(1+สมมติฐาน!B22)^(16-1)+MAX(0,สมมติฐาน!B32*(1-สมมติฐาน!B8)^(16-1)-สมมติฐาน!B34)*สมมติฐาน!B25)*365 -> 28938.225 | F20: =E20-สมมติฐาน!B28 -> 25438.225 | G20: =G19+F20 -> 219496.73 | I20: =สมมติฐาน!B32*(1-สมมติฐาน!B8)^(16-1)*365 -> 6855.8941 | J20: =(MIN(สมมติฐาน!B32*(1-สมมติฐาน!B8)^(16-1),สมมติฐาน!B34)+MIN(สมมติฐาน!B35,(MIN(MAX(0,สมมติฐาน!B32*(1-สมมติฐาน!B8)^(16-1)-สมมติฐาน!B34),สมมติฐาน!B12*สมมติฐาน!B14))*สมมติฐาน!B15))*365 -> 5902.2 | K20: =MAX(0,MAX(0,สมมติฐาน!B32*(1-สมมติฐาน!B8)^(16-1)-สมมติฐาน!B34)-สมมติฐาน!B12*สมมติฐาน!B14)*365 -> 690.89414 | L20: =((MIN(สมมติฐาน!B32*(1-สมมติฐาน!B8)^(16-1),สมมติฐาน!B34)+MIN(สมมติฐาน!B35,(MIN(MAX(0,สมมติฐาน!B32*(1-สมมติฐาน!B8)^(16-1)-สมมติฐาน!B34),สมมติฐาน!B12*สมมติฐาน!B14))*สมมติฐาน!B15))*สมมติฐาน!B21*(1+สมมติฐาน!B22)^(16-1)+MAX(0,MAX(0,สมมติฐาน!B32*(1-สมมติฐาน!B8)^(16-1)-สมมติฐาน!B34)-สมมติฐาน!B12*สมมติฐาน!B14)*สมมติฐาน!B25)*365 -> 42899.426 | M20: =L20-สมมติฐาน!B28 -> 39399.426 | N20: =N19+M20 -> 217996.3 | P20: =-สมมติฐาน!B33*365*สมมติฐาน!B21*(1+สมมติฐาน!B22)^(16-1) -> -50478.144 | Q20: =Q19+P20 -> -653082.95
A21: 17 | B21: =สมมติฐาน!B32*(1-สมมติฐาน!B8)^(17-1)*365 -> 6821.6147 | C21: =MIN(สมมติฐาน!B32*(1-สมมติฐาน!B8)^(17-1),สมมติฐาน!B34)*365 -> 2880 | D21: =MAX(0,สมมติฐาน!B32*(1-สมมติฐาน!B8)^(17-1)-สมมติฐาน!B34)*365 -> 3941.6147 | E21: =(MIN(สมมติฐาน!B32*(1-สมมติฐาน!B8)^(17-1),สมมติฐาน!B34)*สมมติฐาน!B21*(1+สมมติฐาน!B22)^(17-1)+MAX(0,สมมติฐาน!B32*(1-สมมติฐาน!B8)^(17-1)-สมมติฐาน!B34)*สมมติฐาน!B25)*365 -> 29468.548 | F21: =E21-สมมติฐาน!B28 -> 25968.548 | G21: =G20+F21 -> 245465.27 | I21: =สมมติฐาน!B32*(1-สมมติฐาน!B8)^(17-1)*365 -> 6821.6147 | J21: =(MIN(สมมติฐาน!B32*(1-สมมติฐาน!B8)^(17-1),สมมติฐาน!B34)+MIN(สมมติฐาน!B35,(MIN(MAX(0,สมมติฐาน!B32*(1-สมมติฐาน!B8)^(17-1)-สมมติฐาน!B34),สมมติฐาน!B12*สมมติฐาน!B14))*สมมติฐาน!B15))*365 -> 5902.2 | K21: =MAX(0,MAX(0,สมมติฐาน!B32*(1-สมมติฐาน!B8)^(17-1)-สมมติฐาน!B34)-สมมติฐาน!B12*สมมติฐาน!B14)*365 -> 656.61467 | L21: =((MIN(สมมติฐาน!B32*(1-สมมติฐาน!B8)^(17-1),สมมติฐาน!B34)+MIN(สมมติฐาน!B35,(MIN(MAX(0,สมมติฐาน!B32*(1-สมมติฐาน!B8)^(17-1)-สมมติฐาน!B34),สมมติฐาน!B12*สมมติฐาน!B14))*สมมติฐาน!B15))*สมมติฐาน!B21*(1+สมมติฐาน!B22)^(17-1)+MAX(0,MAX(0,สมมติฐาน!B32*(1-สมมติฐาน!B8)^(17-1)-สมมติฐาน!B34)-สมมติฐาน!B12*สมมติฐาน!B14)*สมมติฐาน!B25)*365 -> 44065.395 | M21: =L21-สมมติฐาน!B28 -> 40565.395 | N21: =N20+M21 -> 258561.69 | P21: =-สมมติฐาน!B33*365*สมมติฐาน!B21*(1+สมมติฐาน!B22)^(17-1) -> -51992.489 | Q21: =Q20+P21 -> -705075.44
A22: 18 | B22: =สมมติฐาน!B32*(1-สมมติฐาน!B8)^(18-1)*365 -> 6787.5066 | C22: =MIN(สมมติฐาน!B32*(1-สมมติฐาน!B8)^(18-1),สมมติฐาน!B34)*365 -> 2880 | D22: =MAX(0,สมมติฐาน!B32*(1-สมมติฐาน!B8)^(18-1)-สมมติฐาน!B34)*365 -> 3907.5066 | E22: =(MIN(สมมติฐาน!B32*(1-สมมติฐาน!B8)^(18-1),สมมติฐาน!B34)*สมมติฐาน!B21*(1+สมมติฐาน!B22)^(18-1)+MAX(0,สมมติฐาน!B32*(1-สมมติฐาน!B8)^(18-1)-สมมติฐาน!B34)*สมมติฐาน!B25)*365 -> 30017.42 | F22: =E22-สมมติฐาน!B28 -> 26517.42 | G22: =G21+F22 -> 271982.69 | I22: =สมมติฐาน!B32*(1-สมมติฐาน!B8)^(18-1)*365 -> 6787.5066 | J22: =(MIN(สมมติฐาน!B32*(1-สมมติฐาน!B8)^(18-1),สมมติฐาน!B34)+MIN(สมมติฐาน!B35,(MIN(MAX(0,สมมติฐาน!B32*(1-สมมติฐาน!B8)^(18-1)-สมมติฐาน!B34),สมมติฐาน!B12*สมมติฐาน!B14))*สมมติฐาน!B15))*365 -> 5902.2 | K22: =MAX(0,MAX(0,สมมติฐาน!B32*(1-สมมติฐาน!B8)^(18-1)-สมมติฐาน!B34)-สมมติฐาน!B12*สมมติฐาน!B14)*365 -> 622.5066 | L22: =((MIN(สมมติฐาน!B32*(1-สมมติฐาน!B8)^(18-1),สมมติฐาน!B34)+MIN(สมมติฐาน!B35,(MIN(MAX(0,สมมติฐาน!B32*(1-สมมติฐาน!B8)^(18-1)-สมมติฐาน!B34),สมมติฐาน!B12*สมมติฐาน!B14))*สมมติฐาน!B15))*สมมติฐาน!B21*(1+สมมติฐาน!B22)^(18-1)+MAX(0,MAX(0,สมมติฐาน!B32*(1-สมมติฐาน!B8)^(18-1)-สมมติฐาน!B34)-สมมติฐาน!B12*สมมติฐาน!B14)*สมมติฐาน!B25)*365 -> 45268.982 | M22: =L22-สมมติฐาน!B28 -> 41768.982 | N22: =N21+M22 -> 300330.67 | P22: =-สมมติฐาน!B33*365*สมมติฐาน!B21*(1+สมมติฐาน!B22)^(18-1) -> -53552.263 | Q22: =Q21+P22 -> -758627.71
A23: 19 | B23: =สมมติฐาน!B32*(1-สมมติฐาน!B8)^(19-1)*365 -> 6753.5691 | C23: =MIN(สมมติฐาน!B32*(1-สมมติฐาน!B8)^(19-1),สมมติฐาน!B34)*365 -> 2880 | D23: =MAX(0,สมมติฐาน!B32*(1-สมมติฐาน!B8)^(19-1)-สมมติฐาน!B34)*365 -> 3873.5691 | E23: =(MIN(สมมติฐาน!B32*(1-สมมติฐาน!B8)^(19-1),สมมติฐาน!B34)*สมมติฐาน!B21*(1+สมมติฐาน!B22)^(19-1)+MAX(0,สมมติฐาน!B32*(1-สมมติฐาน!B8)^(19-1)-สมมติฐาน!B34)*สมมติฐาน!B25)*365 -> 30585.384 | F23: =E23-สมมติฐาน!B28 -> 27085.384 | G23: =G22+F23 -> 299068.08 | I23: =สมมติฐาน!B32*(1-สมมติฐาน!B8)^(19-1)*365 -> 6753.5691 | J23: =(MIN(สมมติฐาน!B32*(1-สมมติฐาน!B8)^(19-1),สมมติฐาน!B34)+MIN(สมมติฐาน!B35,(MIN(MAX(0,สมมติฐาน!B32*(1-สมมติฐาน!B8)^(19-1)-สมมติฐาน!B34),สมมติฐาน!B12*สมมติฐาน!B14))*สมมติฐาน!B15))*365 -> 5902.2 | K23: =MAX(0,MAX(0,สมมติฐาน!B32*(1-สมมติฐาน!B8)^(19-1)-สมมติฐาน!B34)-สมมติฐาน!B12*สมมติฐาน!B14)*365 -> 588.56906 | L23: =((MIN(สมมติฐาน!B32*(1-สมมติฐาน!B8)^(19-1),สมมติฐาน!B34)+MIN(สมมติฐาน!B35,(MIN(MAX(0,สมมติฐาน!B32*(1-สมมติฐาน!B8)^(19-1)-สมมติฐาน!B34),สมมติฐาน!B12*สมมติฐาน!B14))*สมมติฐาน!B15))*สมมติฐาน!B21*(1+สมมติฐาน!B22)^(19-1)+MAX(0,MAX(0,สมมติฐาน!B32*(1-สมมติฐาน!B8)^(19-1)-สมมติฐาน!B34)-สมมติฐาน!B12*สมมติฐาน!B14)*สมมติฐาน!B25)*365 -> 46511.304 | M23: =L23-สมมติฐาน!B28 -> 43011.304 | N23: =N22+M23 -> 343341.98 | P23: =-สมมติฐาน!B33*365*สมมติฐาน!B21*(1+สมมติฐาน!B22)^(19-1) -> -55158.831 | Q23: =Q22+P23 -> -813786.54
A24: 20 | B24: =สมมติฐาน!B32*(1-สมมติฐาน!B8)^(20-1)*365 -> 6719.8012 | C24: =MIN(สมมติฐาน!B32*(1-สมมติฐาน!B8)^(20-1),สมมติฐาน!B34)*365 -> 2880 | D24: =MAX(0,สมมติฐาน!B32*(1-สมมติฐาน!B8)^(20-1)-สมมติฐาน!B34)*365 -> 3839.8012 | E24: =(MIN(สมมติฐาน!B32*(1-สมมติฐาน!B8)^(20-1),สมมติฐาน!B34)*สมมติฐาน!B21*(1+สมมติฐาน!B22)^(20-1)+MAX(0,สมมติฐาน!B32*(1-สมมติฐาน!B8)^(20-1)-สมมติฐาน!B34)*สมมติฐาน!B25)*365 -> 31173.001 | F24: =E24-สมมติฐาน!B28 -> 27673.001 | G24: =G23+F24 -> 326741.08 | I24: =สมมติฐาน!B32*(1-สมมติฐาน!B8)^(20-1)*365 -> 6719.8012 | J24: =(MIN(สมมติฐาน!B32*(1-สมมติฐาน!B8)^(20-1),สมมติฐาน!B34)+MIN(สมมติฐาน!B35,(MIN(MAX(0,สมมติฐาน!B32*(1-สมมติฐาน!B8)^(20-1)-สมมติฐาน!B34),สมมติฐาน!B12*สมมติฐาน!B14))*สมมติฐาน!B15))*365 -> 5902.2 | K24: =MAX(0,MAX(0,สมมติฐาน!B32*(1-สมมติฐาน!B8)^(20-1)-สมมติฐาน!B34)-สมมติฐาน!B12*สมมติฐาน!B14)*365 -> 554.80122 | L24: =((MIN(สมมติฐาน!B32*(1-สมมติฐาน!B8)^(20-1),สมมติฐาน!B34)+MIN(สมมติฐาน!B35,(MIN(MAX(0,สมมติฐาน!B32*(1-สมมติฐาน!B8)^(20-1)-สมมติฐาน!B34),สมมติฐาน!B12*สมมติฐาน!B14))*สมมติฐาน!B15))*สมมติฐาน!B21*(1+สมมติฐาน!B22)^(20-1)+MAX(0,MAX(0,สมมติฐาน!B32*(1-สมมติฐาน!B8)^(20-1)-สมมติฐาน!B34)-สมมติฐาน!B12*สมมติฐาน!B14)*สมมติฐาน!B25)*365 -> 47793.508 | M24: =L24-สมมติฐาน!B28 -> 44293.508 | N24: =N23+M24 -> 387635.49 | P24: =-สมมติฐาน!B33*365*สมมติฐาน!B21*(1+สมมติฐาน!B22)^(20-1) -> -56813.596 | Q24: =Q23+P24 -> -870600.13
A25: 21 | B25: =สมมติฐาน!B32*(1-สมมติฐาน!B8)^(21-1)*365 -> 6686.2022 | C25: =MIN(สมมติฐาน!B32*(1-สมมติฐาน!B8)^(21-1),สมมติฐาน!B34)*365 -> 2880 | D25: =MAX(0,สมมติฐาน!B32*(1-สมมติฐาน!B8)^(21-1)-สมมติฐาน!B34)*365 -> 3806.2022 | E25: =(MIN(สมมติฐาน!B32*(1-สมมติฐาน!B8)^(21-1),สมมติฐาน!B34)*สมมติฐาน!B21*(1+สมมติฐาน!B22)^(21-1)+MAX(0,สมมติฐาน!B32*(1-สมมติฐาน!B8)^(21-1)-สมมติฐาน!B34)*สมมติฐาน!B25)*365 -> 31780.846 | F25: =E25-สมมติฐาน!B28 -> 28280.846 | G25: =G24+F25 -> 355021.93 | I25: =สมมติฐาน!B32*(1-สมมติฐาน!B8)^(21-1)*365 -> 6686.2022 | J25: =(MIN(สมมติฐาน!B32*(1-สมมติฐาน!B8)^(21-1),สมมติฐาน!B34)+MIN(สมมติฐาน!B35,(MIN(MAX(0,สมมติฐาน!B32*(1-สมมติฐาน!B8)^(21-1)-สมมติฐาน!B34),สมมติฐาน!B12*สมมติฐาน!B14))*สมมติฐาน!B15))*365 -> 5902.2 | K25: =MAX(0,MAX(0,สมมติฐาน!B32*(1-สมมติฐาน!B8)^(21-1)-สมมติฐาน!B34)-สมมติฐาน!B12*สมมติฐาน!B14)*365 -> 521.20221 | L25: =((MIN(สมมติฐาน!B32*(1-สมมติฐาน!B8)^(21-1),สมมติฐาน!B34)+MIN(สมมติฐาน!B35,(MIN(MAX(0,สมมติฐาน!B32*(1-สมมติฐาน!B8)^(21-1)-สมมติฐาน!B34),สมมติฐาน!B12*สมมติฐาน!B14))*สมมติฐาน!B15))*สมมติฐาน!B21*(1+สมมติฐาน!B22)^(21-1)+MAX(0,MAX(0,สมมติฐาน!B32*(1-สมมติฐาน!B8)^(21-1)-สมมติฐาน!B34)-สมมติฐาน!B12*สมมติฐาน!B14)*สมมติฐาน!B25)*365 -> 49116.779 | M25: =L25-สมมติฐาน!B28-สมมติฐาน!B13 -> -34383.221 | N25: =N24+M25 -> 353252.26 | P25: =-สมมติฐาน!B33*365*สมมติฐาน!B21*(1+สมมติฐาน!B22)^(21-1) -> -58518.004 | Q25: =Q24+P25 -> -929118.14
A26: 22 | B26: =สมมติฐาน!B32*(1-สมมติฐาน!B8)^(22-1)*365 -> 6652.7712 | C26: =MIN(สมมติฐาน!B32*(1-สมมติฐาน!B8)^(22-1),สมมติฐาน!B34)*365 -> 2880 | D26: =MAX(0,สมมติฐาน!B32*(1-สมมติฐาน!B8)^(22-1)-สมมติฐาน!B34)*365 -> 3772.7712 | E26: =(MIN(สมมติฐาน!B32*(1-สมมติฐาน!B8)^(22-1),สมมติฐาน!B34)*สมมติฐาน!B21*(1+สมมติฐาน!B22)^(22-1)+MAX(0,สมมติฐาน!B32*(1-สมมติฐาน!B8)^(22-1)-สมมติฐาน!B34)*สมมติฐาน!B25)*365 -> 32409.514 | F26: =E26-สมมติฐาน!B28 -> 28909.514 | G26: =G25+F26 -> 383931.44 | I26: =สมมติฐาน!B32*(1-สมมติฐาน!B8)^(22-1)*365 -> 6652.7712 | J26: =(MIN(สมมติฐาน!B32*(1-สมมติฐาน!B8)^(22-1),สมมติฐาน!B34)+MIN(สมมติฐาน!B35,(MIN(MAX(0,สมมติฐาน!B32*(1-สมมติฐาน!B8)^(22-1)-สมมติฐาน!B34),สมมติฐาน!B12*สมมติฐาน!B14))*สมมติฐาน!B15))*365 -> 5902.2 | K26: =MAX(0,MAX(0,สมมติฐาน!B32*(1-สมมติฐาน!B8)^(22-1)-สมมติฐาน!B34)-สมมติฐาน!B12*สมมติฐาน!B14)*365 -> 487.7712 | L26: =((MIN(สมมติฐาน!B32*(1-สมมติฐาน!B8)^(22-1),สมมติฐาน!B34)+MIN(สมมติฐาน!B35,(MIN(MAX(0,สมมติฐาน!B32*(1-สมมติฐาน!B8)^(22-1)-สมมติฐาน!B34),สมมติฐาน!B12*สมมติฐาน!B14))*สมมติฐาน!B15))*สมมติฐาน!B21*(1+สมมติฐาน!B22)^(22-1)+MAX(0,MAX(0,สมมติฐาน!B32*(1-สมมติฐาน!B8)^(22-1)-สมมติฐาน!B34)-สมมติฐาน!B12*สมมติฐาน!B14)*สมมติฐาน!B25)*365 -> 50482.334 | M26: =L26-สมมติฐาน!B28 -> 46982.334 | N26: =N25+M26 -> 400234.6 | P26: =-สมมติฐาน!B33*365*สมมติฐาน!B21*(1+สมมติฐาน!B22)^(22-1) -> -60273.544 | Q26: =Q25+P26 -> -989391.68
A27: 23 | B27: =สมมติฐาน!B32*(1-สมมติฐาน!B8)^(23-1)*365 -> 6619.5073 | C27: =MIN(สมมติฐาน!B32*(1-สมมติฐาน!B8)^(23-1),สมมติฐาน!B34)*365 -> 2880 | D27: =MAX(0,สมมติฐาน!B32*(1-สมมติฐาน!B8)^(23-1)-สมมติฐาน!B34)*365 -> 3739.5073 | E27: =(MIN(สมมติฐาน!B32*(1-สมมติฐาน!B8)^(23-1),สมมติฐาน!B34)*สมมติฐาน!B21*(1+สมมติฐาน!B22)^(23-1)+MAX(0,สมมติฐาน!B32*(1-สมมติฐาน!B8)^(23-1)-สมมติฐาน!B34)*สมมติฐาน!B25)*365 -> 33059.616 | F27: =E27-สมมติฐาน!B28 -> 29559.616 | G27: =G26+F27 -> 413491.06 | I27: =สมมติฐาน!B32*(1-สมมติฐาน!B8)^(23-1)*365 -> 6619.5073 | J27: =(MIN(สมมติฐาน!B32*(1-สมมติฐาน!B8)^(23-1),สมมติฐาน!B34)+MIN(สมมติฐาน!B35,(MIN(MAX(0,สมมติฐาน!B32*(1-สมมติฐาน!B8)^(23-1)-สมมติฐาน!B34),สมมติฐาน!B12*สมมติฐาน!B14))*สมมติฐาน!B15))*365 -> 5902.2 | K27: =MAX(0,MAX(0,สมมติฐาน!B32*(1-สมมติฐาน!B8)^(23-1)-สมมติฐาน!B34)-สมมติฐาน!B12*สมมติฐาน!B14)*365 -> 454.50735 | L27: =((MIN(สมมติฐาน!B32*(1-สมมติฐาน!B8)^(23-1),สมมติฐาน!B34)+MIN(สมมติฐาน!B35,(MIN(MAX(0,สมมติฐาน!B32*(1-สมมติฐาน!B8)^(23-1)-สมมติฐาน!B34),สมมติฐาน!B12*สมมติฐาน!B14))*สมมติฐาน!B15))*สมมติฐาน!B21*(1+สมมติฐาน!B22)^(23-1)+MAX(0,MAX(0,สมมติฐาน!B32*(1-สมมติฐาน!B8)^(23-1)-สมมติฐาน!B34)-สมมติฐาน!B12*สมมติฐาน!B14)*สมมติฐาน!B25)*365 -> 51891.431 | M27: =L27-สมมติฐาน!B28 -> 48391.431 | N27: =N26+M27 -> 448626.03 | P27: =-สมมติฐาน!B33*365*สมมติฐาน!B21*(1+สมมติฐาน!B22)^(23-1) -> -62081.75 | Q27: =Q26+P27 -> -1051473.4
A28: 24 | B28: =สมมติฐาน!B32*(1-สมมติฐาน!B8)^(24-1)*365 -> 6586.4098 | C28: =MIN(สมมติฐาน!B32*(1-สมมติฐาน!B8)^(24-1),สมมติฐาน!B34)*365 -> 2880 | D28: =MAX(0,สมมติฐาน!B32*(1-สมมติฐาน!B8)^(24-1)-สมมติฐาน!B34)*365 -> 3706.4098 | E28: =(MIN(สมมติฐาน!B32*(1-สมมติฐาน!B8)^(24-1),สมมติฐาน!B34)*สมมติฐาน!B21*(1+สมมติฐาน!B22)^(24-1)+MAX(0,สมมติฐาน!B32*(1-สมมติฐาน!B8)^(24-1)-สมมติฐาน!B34)*สมมติฐาน!B25)*365 -> 33731.783 | F28: =E28-สมมติฐาน!B28 -> 30231.783 | G28: =G27+F28 -> 443722.84 | I28: =สมมติฐาน!B32*(1-สมมติฐาน!B8)^(24-1)*365 -> 6586.4098 | J28: =(MIN(สมมติฐาน!B32*(1-สมมติฐาน!B8)^(24-1),สมมติฐาน!B34)+MIN(สมมติฐาน!B35,(MIN(MAX(0,สมมติฐาน!B32*(1-สมมติฐาน!B8)^(24-1)-สมมติฐาน!B34),สมมติฐาน!B12*สมมติฐาน!B14))*สมมติฐาน!B15))*365 -> 5902.2 | K28: =MAX(0,MAX(0,สมมติฐาน!B32*(1-สมมติฐาน!B8)^(24-1)-สมมติฐาน!B34)-สมมติฐาน!B12*สมมติฐาน!B14)*365 -> 421.40981 | L28: =((MIN(สมมติฐาน!B32*(1-สมมติฐาน!B8)^(24-1),สมมติฐาน!B34)+MIN(สมมติฐาน!B35,(MIN(MAX(0,สมมติฐาน!B32*(1-สมมติฐาน!B8)^(24-1)-สมมติฐาน!B34),สมมติฐาน!B12*สมมติฐาน!B14))*สมมติฐาน!B15))*สมมติฐาน!B21*(1+สมมติฐาน!B22)^(24-1)+MAX(0,MAX(0,สมมติฐาน!B32*(1-สมมติฐาน!B8)^(24-1)-สมมติฐาน!B34)-สมมติฐาน!B12*สมมติฐาน!B14)*สมมติฐาน!B25)*365 -> 53345.362 | M28: =L28-สมมติฐาน!B28 -> 49845.362 | N28: =N27+M28 -> 498471.39 | P28: =-สมมติฐาน!B33*365*สมมติฐาน!B21*(1+สมมติฐาน!B22)^(24-1) -> -63944.203 | Q28: =Q27+P28 -> -1115417.6
A29: 25 | B29: =สมมติฐาน!B32*(1-สมมติฐาน!B8)^(25-1)*365 -> 6553.4778 | C29: =MIN(สมมติฐาน!B32*(1-สมมติฐาน!B8)^(25-1),สมมติฐาน!B34)*365 -> 2880 | D29: =MAX(0,สมมติฐาน!B32*(1-สมมติฐาน!B8)^(25-1)-สมมติฐาน!B34)*365 -> 3673.4778 | E29: =(MIN(สมมติฐาน!B32*(1-สมมติฐาน!B8)^(25-1),สมมติฐาน!B34)*สมมติฐาน!B21*(1+สมมติฐาน!B22)^(25-1)+MAX(0,สมมติฐาน!B32*(1-สมมติฐาน!B8)^(25-1)-สมมติฐาน!B34)*สมมติฐาน!B25)*365 -> 34426.663 | F29: =E29-สมมติฐาน!B28 -> 30926.663 | G29: =G28+F29 -> 474649.5 | I29: =สมมติฐาน!B32*(1-สมมติฐาน!B8)^(25-1)*365 -> 6553.4778 | J29: =(MIN(สมมติฐาน!B32*(1-สมมติฐาน!B8)^(25-1),สมมติฐาน!B34)+MIN(สมมติฐาน!B35,(MIN(MAX(0,สมมติฐาน!B32*(1-สมมติฐาน!B8)^(25-1)-สมมติฐาน!B34),สมมติฐาน!B12*สมมติฐาน!B14))*สมมติฐาน!B15))*365 -> 5902.2 | K29: =MAX(0,MAX(0,สมมติฐาน!B32*(1-สมมติฐาน!B8)^(25-1)-สมมติฐาน!B34)-สมมติฐาน!B12*สมมติฐาน!B14)*365 -> 388.47776 | L29: =((MIN(สมมติฐาน!B32*(1-สมมติฐาน!B8)^(25-1),สมมติฐาน!B34)+MIN(สมมติฐาน!B35,(MIN(MAX(0,สมมติฐาน!B32*(1-สมมติฐาน!B8)^(25-1)-สมมติฐาน!B34),สมมติฐาน!B12*สมมติฐาน!B14))*สมมติฐาน!B15))*สมมติฐาน!B21*(1+สมมติฐาน!B22)^(25-1)+MAX(0,MAX(0,สมมติฐาน!B32*(1-สมมติฐาน!B8)^(25-1)-สมมติฐาน!B34)-สมมติฐาน!B12*สมมติฐาน!B14)*สมมติฐาน!B25)*365 -> 54845.459 | M29: =L29-สมมติฐาน!B28 -> 51345.459 | N29: =N28+M29 -> 549816.85 | P29: =-สมมติฐาน!B33*365*สมมติฐาน!B21*(1+สมมติฐาน!B22)^(25-1) -> -65862.529 | Q29: =Q28+P29 -> -1181280.2
A31: สรุป
A32: รายจ่ายรวม (ลงทุน+บำรุง) (฿)
A33: รายรับรวม 25 ปี (ประหยัด+FiT) (฿) | B33: =สมมติฐาน!B5+สมมติฐาน!B28*สมมติฐาน!B9 -> 222500 | I33: =สมมติฐาน!B5+สมมติฐาน!B13+สมมติฐาน!B28*สมมติฐาน!B9 -> 302500
A34: กำไรสุทธิ 25 ปี (฿) | B34: =SUM(E5:E29) -> 697149.5 | I34: =SUM(L5:L29) -> 1012316.9 | P34: =SUM(P5:P29) -> -1181280.2
A35: Payback Period เบื้องต้น (ปี) | B35: =B34-B33 -> 474649.5 | I35: =I34-I33 -> 709816.85 | P35: -
A36: NPV 25 ปี (฿) | B36: =IFERROR(สมมติฐาน!B5/((SUM(E5:E29)-สมมติฐาน!B28*สมมติฐาน!B9)/สมมติฐาน!B9),"N/A") -> 5.5359678 | I36: =IFERROR((สมมติฐาน!B5+สมมติฐาน!B13)/((SUM(L5:L29)-สมมติฐาน!B28*สมมติฐาน!B9)/สมมติฐาน!B9),"N/A") -> 5.8119616
B37: =F5/((1+สมมติฐาน!B29)^1)+F6/((1+สมมติฐาน!B29)^2)+F7/((1+สมมติฐาน!B29)^3)+F8/((1+สมมติฐาน!B29)^4)+F9/((1+สมมติฐาน!B29)^5)+F10/((1+สมมติฐาน!B29)^6)+F11/((1+สมมติฐาน!B29)^7)+F12/((1+สมมติฐาน!B29)^8)+F13/((1+สมมติฐาน!B29)^9)+F14/((1+สมมติฐาน!B29)^10)+F15/((1+สมมติฐาน!B29)^11)+F16/((1+สมมติฐาน!B29)^12)+F17/((1+สมมติฐาน!B29)^13)+F18/((1+สมมติฐาน!B29)^14)+F19/((1+สมมติฐาน!B29)^15)+F20/((1+สมมติฐาน!B29)^16)+F21/((1+สมมติฐาน!B29)^17)+F22/((1+สมมติฐาน!B29)^18)+F23/((1+สมมติฐาน!B29)^19)+F24/((1+สมมติฐาน!B29)^20)+F25/((1+สมมติฐาน!B29)^21)+F26/((1+สมมติฐาน!B29)^22)+F27/((1+สมมติฐาน!B29)^23)+F28/((1+สมมติฐาน!B29)^24)+F29/((1+สมมติฐาน!B29)^25) -> 198769.8 | I37: =M5/((1+สมมติฐาน!B29)^1)+M6/((1+สมมติฐาน!B29)^2)+M7/((1+สมมติฐาน!B29)^3)+M8/((1+สมมติฐาน!B29)^4)+M9/((1+สมมติฐาน!B29)^5)+M10/((1+สมมติฐาน!B29)^6)+M11/((1+สมมติฐาน!B29)^7)+M12/((1+สมมติฐาน!B29)^8)+M13/((1+สมมติฐาน!B29)^9)+M14/((1+สมมติฐาน!B29)^10)+M15/((1+สมมติฐาน!B29)^11)+M16/((1+สมมติฐาน!B29)^12)+M17/((1+สมมติฐาน!B29)^13)+M18/((1+สมมติฐาน!B29)^14)+M19/((1+สมมติฐาน!B29)^15)+M20/((1+สมมติฐาน!B29)^16)+M21/((1+สมมติฐาน!B29)^17)+M22/((1+สมมติฐาน!B29)^18)+M23/((1+สมมติฐาน!B29)^19)+M24/((1+สมมติฐาน!B29)^20)+M25/((1+สมมติฐาน!B29)^21)+M26/((1+สมมติฐาน!B29)^22)+M27/((1+สมมติฐาน!B29)^23)+M28/((1+สมมติฐาน!B29)^24)+M29/((1+สมมติฐาน!B29)^25) -> 204787.81

Sheet Sensitivity
A1: Sensitivity Analysis — Payback Period (ปี) | 🟢 <8 ปี 🟡 8-12 ปี 🔴 >12 ปี
A3: กรณี 1: ไม่มีแบต — Payback Period (ปี)
A4: FiT ↓ / ค่าไฟ → | B4: 3 | C4: 3.5 | D4: 4 | E4: 4.5 | F4: 5 | G4: 5.5 | H4: 6
A5: 1 | B5: =IF(MIN(สมมติฐาน!B32,สมมติฐาน!B34)*365*3+MAX(0,สมมติฐาน!B32-สมมติฐาน!B34)*365*1-สมมติฐาน!B28>0,สมมติฐาน!B5/(MIN(สมมติฐาน!B32,สมมติฐาน!B34)*365*3+MAX(0,สมมติฐาน!B32-สมมติฐาน!B34)*365*1-สมมติฐาน!B28),999) -> 13.987825 | C5: =IF(MIN(สมมติฐาน!B32,สมมติฐาน!B34)*365*3.5+MAX(0,สมมติฐาน!B32-สมมติฐาน!B34)*365*1-สมมติฐาน!B28>0,สมมติฐาน!B5/(MIN(สมมติฐาน!B32,สมมติฐาน!B34)*365*3.5+MAX(0,สมมติฐาน!B32-สมมติฐาน!B34)*365*1-สมมติฐาน!B28),999) -> 12.171757 | D5: =IF(MIN(สมมติฐาน!B32,สมมติฐาน!B34)*365*4+MAX(0,สมมติฐาน!B32-สมมติฐาน!B34)*365*1-สมมติฐาน!B28>0,สมมติฐาน!B5/(MIN(สมมติฐาน!B32,สมมติฐาน!B34)*365*4+MAX(0,สมมติฐาน!B32-สมมติฐาน!B34)*365*1-สมมติฐาน!B28),999) -> 10.773067 | E5: =IF(MIN(สมมติฐาน!B32,สมมติฐาน!B34)*365*4.5+MAX(0,สมมติฐาน!B32-สมมติฐาน!B34)*365*1-สมมติฐาน!B28>0,สมมติฐาน!B5/(MIN(สมมติฐาน!B32,สมมติฐาน!B34)*365*4.5+MAX(0,สมมติฐาน!B32-สมมติฐาน!B34)*365*1-สมมติฐาน!B28),999) -> 9.6627002 | F5: =IF(MIN(สมมติฐาน!B32,สมมติฐาน!B34)*365*5+MAX(0,สมมติฐาน!B32-สมมติฐาน!B34)*365*1-สมมติฐาน!B28>0,สมมติฐาน!B5/(MIN(สมมติฐาน!B32,สมมติฐาน!B34)*365*5+MAX(0,สมมติฐาน!B32-สมมติฐาน!B34)*365*1-สมมติฐาน!B28),999) -> 8.7598345 | G5: =IF(MIN(สมมติฐาน!B32,สมมติฐาน!B34)*365*5.5+MAX(0,สมมติฐาน!B32-สมมติฐาน!B34)*365*1-สมมติฐาน!B28>0,สมมติฐาน!B5/(MIN(สมมติฐาน!B32,สมมติฐาน!B34)*365*5.5+MAX(0,สมมติฐาน!B32-สมมติฐาน!B34)*365*1-สมมติฐาน!B28),999) -> 8.0112751 | H5: =IF(MIN(สมมติฐาน!B32,สมมติฐาน!B34)*365*6+MAX(0,สมมติฐาน!B32-สมมติฐาน!B34)*365*1-สมมติฐาน!B28>0,สมมติฐาน!B5/(MIN(สมมติฐาน!B32,สมมติฐาน!B34)*365*6+MAX(0,สมมติฐาน!B32-สมมติฐาน!B34)*365*1-สมมติฐาน!B28),999) -> 7.3805781
A6: 1.5 | B6: =IF(MIN(สมมติฐาน!B32,สมมติฐาน!B34)*365*3+MAX(0,สมมติฐาน!B32-สมมติฐาน!B34)*365*1.5-สมมติฐาน!B28>0,สมมติฐาน!B5/(MIN(สมมติฐาน!B32,สมมติฐาน!B34)*365*3+MAX(0,สมมติฐาน!B32-สมมติฐาน!B34)*365*1.5-สมมติฐาน!B28),999) -> 11.337988 | C6: =IF(MIN(สมมติฐาน!B32,สมมติฐาน!B34)*365*3.5+MAX(0,สมมติฐาน!B32-สมมติฐาน!B34)*365*1.5-สมมติฐาน!B28>0,สมมติฐาน!B5/(MIN(สมมติฐาน!B32,สมมติฐาน!B34)*365*3.5+MAX(0,สมมติฐาน!B32-สมมติฐาน!B34)*365*1.5-สมมติฐาน!B28),999) -> 10.114727 | D6: =IF(MIN(สมมติฐาน!B32,สมมติฐาน!B34)*365*4+MAX(0,สมมติฐาน!B32-สมมติฐาน!B34)*365*1.5-สมมติฐาน!B28>0,สมมติฐาน!B5/(MIN(สมมติฐาน!B32,สมมติฐาน!B34)*365*4+MAX(0,สมมติฐาน!B32-สมมติฐาน!B34)*365*1.5-สมมติฐาน!B28),999) -> 9.1297181 | E6: =IF(MIN(สมมติฐาน!B32,สมมติฐาน!B34)*365*4.5+MAX(0,สมมติฐาน!B32-สมมติฐาน!B34)*365*1.5-สมมติฐาน!B28>0,สมมติฐาน!B5/(MIN(สมมติฐาน!B32,สมมติฐาน!B34)*365*4.5+MAX(0,สมมติฐาน!B32-สมมติฐาน!B34)*365*1.5-สมมติฐาน!B28),999) -> 8.3195316 | F6: =IF(MIN(สมมติฐาน!B32,สมมติฐาน!B34)*365*5+MAX(0,สมมติฐาน!B32-สมมติฐาน!B34)*365*1.5-สมมติฐาน!B28>0,สมมติฐาน!B5/(MIN(สมมติฐาน!B32,สมมติฐาน!B34)*365*5+MAX(0,สมมติฐาน!B32-สมมติฐาน!B34)*365*1.5-สมมติฐาน!B28),999) -> 7.6414193 | G6: =IF(MIN(สมมติฐาน!B32,สมมติฐาน!B34)*365*5.5+MAX(0,สมมติฐาน!B32-สมมติฐาน!B34)*365*1.5-สมมติฐาน!B28>0,สมมติฐาน!B5/(MIN(สมมติฐาน!B32,สมมติฐาน!B34)*365*5.5+MAX(0,สมมติฐาน!B32-สมมติฐาน!B34)*365*1.5-สมมติฐาน!B28),999) -> 7.0655196 | H6: =IF(MIN(สมมติฐาน!B32,สมมติฐาน!B34)*365*6+MAX(0,สมมติฐาน!B32-สมมติฐาน!B34)*365*1.5-สมมติฐาน!B28>0,สมมติฐาน!B5/(MIN(สมมติฐาน!B32,สมมติฐาน!B34)*365*6+MAX(0,สมมติฐาน!B32-สมมติฐาน!B34)*365*1.5-สมมติฐาน!B28),999) -> 6.5703422
A7: 2 | B7: =IF(MIN(สมมติฐาน!B32,สมมติฐาน!B34)*365*3+MAX(0,สมมติฐาน!B32-สมมติฐาน!B34)*365*2-สมมติฐาน!B28>0,สมมติฐาน!B5/(MIN(สมมติฐาน!B32,สมมติฐาน!B34)*365*3+MAX(0,สมมติฐาน!B32-สมมติฐาน!B34)*365*2-สมมติฐาน!B28),999) -> 9.5322154 | C7: =IF(MIN(สมมติฐาน!B32,สมมติฐาน!B34)*365*3.5+MAX(0,สมมติฐาน!B32-สมมติฐาน!B34)*365*2-สมมติฐาน!B28>0,สมมติฐาน!B5/(MIN(สมมติฐาน!B32,สมมติฐาน!B34)*365*3.5+MAX(0,สมมติฐาน!B32-สมมติฐาน!B34)*365*2-สมมติฐาน!B28),999) -> 8.6524595 | D7: =IF(MIN(สมมติฐาน!B32,สมมติฐาน!B34)*365*4+MAX(0,สมมติฐาน!B32-สมมติฐาน!B34)*365*2-สมมติฐาน!B28>0,สมมติฐาน!B5/(MIN(สมมติฐาน!B32,สมมติฐาน!B34)*365*4+MAX(0,สมมติฐาน!B32-สมมติฐาน!B34)*365*2-สมมติฐาน!B28),999) -> 7.921373 | E7: =IF(MIN(สมมติฐาน!B32,สมมติฐาน!B34)*365*4.5+MAX(0,สมมติฐาน!B32-สมมติฐาน!B34)*365*2-สมมติฐาน!B28>0,สมมติฐาน!B5/(MIN(สมมติฐาน!B32,สมมติฐาน!B34)*365*4.5+MAX(0,สมมติฐาน!B32-สมมติฐาน!B34)*365*2-สมมติฐาน!B28),999) -> 7.3042067 | F7: =IF(MIN(สมมติฐาน!B32,สมมติฐาน!B34)*365*5+MAX(0,สมมติฐาน!B32-สมมติฐาน!B34)*365*2-สมมติฐาน!B28>0,สมมติฐาน!B5/(MIN(สมมติฐาน!B32,สมมติฐาน!B34)*365*5+MAX(0,สมมติฐาน!B32-สมมติฐาน!B34)*365*2-สมมติฐาน!B28),999) -> 6.776258 | G7: =IF(MIN(สมมติฐาน!B32,สมมติฐาน!B34)*365*5.5+MAX(0,สมมติฐาน!B32-สมมติฐาน!B34)*365*2-สมมติฐาน!B28>0,สมมติฐาน!B5/(MIN(สมมติฐาน!B32,สมมติฐาน!B34)*365*5.5+MAX(0,สมมติฐาน!B32-สมมติฐาน!B34)*365*2-สมมติฐาน!B28),999) -> 6.3194851 | H7: =IF(MIN(สมมติฐาน!B32,สมมติฐาน!B34)*365*6+MAX(0,สมมติฐาน!B32-สมมติฐาน!B34)*365*2-สมมติฐาน!B28>0,สมมติฐาน!B5/(MIN(สมมติฐาน!B32,สมมติฐาน!B34)*365*6+MAX(0,สมมติฐาน!B32-สมมติฐาน!B34)*365*2-สมมติฐาน!B28),999) -> 5.9204035
A8: 2.2 | B8: =IF(MIN(สมมติฐาน!B32,สมมติฐาน!B34)*365*3+MAX(0,สมมติฐาน!B32-สมมติฐาน!B34)*365*2.2-สมมติฐาน!B28>0,สมมติฐาน!B5/(MIN(สมมติฐาน!B32,สมมติฐาน!B34)*365*3+MAX(0,สมมติฐาน!B32-สมมติฐาน!B34)*365*2.2-สมมติฐาน!B28),999) -> 8.961317 | C8: =IF(MIN(สมมติฐาน!B32,สมมติฐาน!B34)*365*3.5+MAX(0,สมมติฐาน!B32-สมมติฐาน!B34)*365*2.2-สมมติฐาน!B28>0,สมมติฐาน!B5/(MIN(สมมติฐาน!B32,สมมติฐาน!B34)*365*3.5+MAX(0,สมมติฐาน!B32-สมมติฐาน!B34)*365*2.2-สมมติฐาน!B28),999) -> 8.1794635 | D8: =IF(MIN(สมมติฐาน!B32,สมมติฐาน!B34)*365*4+MAX(0,สมมติฐาน!B32-สมมติฐาน!B34)*365*2.2-สมมติฐาน!B28>0,สมมติฐาน!B5/(MIN(สมมติฐาน!B32,สมมติฐาน!B34)*365*4+MAX(0,สมมติฐาน!B32-สมมติฐาน!B34)*365*2.2-สมมติฐาน!B28),999) -> 7.5230917 | E8: =IF(MIN(สมมติฐาน!B32,สมมติฐาน!B34)*365*4.5+MAX(0,สมมติฐาน!B32-สมมติฐาน!B34)*365*2.2-สมมติฐาน!B28>0,สมมติฐาน!B5/(MIN(สมมติฐาน!B32,สมมติฐาน!B34)*365*4.5+MAX(0,สมมติฐาน!B32-สมมติฐาน!B34)*365*2.2-สมมติฐาน!B28),999) -> 6.9642374 | F8: =IF(MIN(สมมติฐาน!B32,สมมติฐาน!B34)*365*5+MAX(0,สมมติฐาน!B32-สมมติฐาน!B34)*365*2.2-สมมติฐาน!B28>0,สมมติฐาน!B5/(MIN(สมมติฐาน!B32,สมมติฐาน!B34)*365*5+MAX(0,สมมติฐาน!B32-สมมติฐาน!B34)*365*2.2-สมมติฐาน!B28),999) -> 6.4826709 | G8: =IF(MIN(สมมติฐาน!B32,สมมติฐาน!B34)*365*5.5+MAX(0,สมมติฐาน!B32-สมมติฐาน!B34)*365*2.2-สมมติฐาน!B28>0,สมมติฐาน!B5/(MIN(สมมติฐาน!B32,สมมติฐาน!B34)*365*5.5+MAX(0,สมมติฐาน!B32-สมมติฐาน!B34)*365*2.2-สมมติฐาน!B28),999) -> 6.0633962 | H8: =IF(MIN(สมมติฐาน!B32,สมมติฐาน!B34)*365*6+MAX(0,สมมติฐาน!B32-สมมติฐาน!B34)*365*2.2-สมมติฐาน!B28>0,สมมติฐาน!B5/(MIN(สมมติฐาน!B32,สมมติฐาน!B34)*365*6+MAX(0,สมมติฐาน!B32-สมมติฐาน!B34)*365*2.2-สมมติฐาน!B28),999) -> 5.6950611
A9: 2.5 | B9: =IF(MIN(สมมติฐาน!B32,สมมติฐาน!B34)*365*3+MAX(0,สมมติฐาน!B32-สมมติฐาน!B34)*365*2.5-สมมติฐาน!B28>0,สมมติฐาน!B5/(MIN(สมมติฐาน!B32,สมมติฐาน!B34)*365*3+MAX(0,สมมติฐาน!B32-สมมติฐาน!B34)*365*2.5-สมมติฐาน!B28),999) -> 8.2226198 | C9: =IF(MIN(สมมติฐาน!B32,สมมติฐาน!B34)*365*3.5+MAX(0,สมมติฐาน!B32-สมมติฐาน!B34)*365*2.5-สมมติฐาน!B28>0,สมมติฐาน!B5/(MIN(สมมติฐาน!B32,สมมติฐาน!B34)*365*3.5+MAX(0,สมมติฐาน!B32-สมมติฐาน!B34)*365*2.5-สมมติฐาน!B28),999) -> 7.5595842 | D9: =IF(MIN(สมมติฐาน!B32,สมมติฐาน!B34)*365*4+MAX(0,สมมติฐาน!B32-สมมติฐาน!B34)*365*2.5-สมมติฐาน!B28>0,สมมติฐาน!B5/(MIN(สมมติฐาน!B32,สมมติฐาน!B34)*365*4+MAX(0,สมมติฐาน!B32-สมมติฐาน!B34)*365*2.5-สมมติฐาน!B28),999) -> 6.9954983 | E9: =IF(MIN(สมมติฐาน!B32,สมมติฐาน!B34)*365*4.5+MAX(0,สมมติฐาน!B32-สมมติฐาน!B34)*365*2.5-สมมติฐาน!B28>0,สมมติฐาน!B5/(MIN(สมมติฐาน!B32,สมมติฐาน!B34)*365*4.5+MAX(0,สมมติฐาน!B32-สมมติฐาน!B34)*365*2.5-สมมติฐาน!B28),999) -> 6.5097496 | F9: =IF(MIN(สมมติฐาน!B32,สมมติฐาน!B34)*365*5+MAX(0,สมมติฐาน!B32-สมมติฐาน!B34)*365*2.5-สมมติฐาน!B28>0,สมมติฐาน!B5/(MIN(สมมติฐาน!B32,สมมติฐาน!B34)*365*5+MAX(0,สมมติฐาน!B32-สมมติฐาน!B34)*365*2.5-สมมติฐาน!B28),999) -> 6.087079 | G9: =IF(MIN(สมมติฐาน!B32,สมมติฐาน!B34)*365*5.5+MAX(0,สมมติฐาน!B32-สมมติฐาน!B34)*365*2.5-สมมติฐาน!B28>0,สมมติฐาน!B5/(MIN(สมมติฐาน!B32,สมมติฐาน!B34)*365*5.5+MAX(0,สมมติฐาน!B32-สมมติฐาน!B34)*365*2.5-สมมติฐาน!B28),999) -> 5.7159491 | H9: =IF(MIN(สมมติฐาน!B32,สมมติฐาน!B34)*365*6+MAX(0,สมมติฐาน!B32-สมมติฐาน!B34)*365*2.5-สมมติฐาน!B28>0,สมมติฐาน!B5/(MIN(สมมติฐาน!B32,สมมติฐาน!B34)*365*6+MAX(0,สมมติฐาน!B32-สมมติฐาน!B34)*365*2.5-สมมติฐาน!B28),999) -> 5.3874741
A10: 3 | B10: =IF(MIN(สมมติฐาน!B32,สมมติฐาน!B34)*365*3+MAX(0,สมมติฐาน!B32-สมมติฐาน!B34)*365*3-สมมติฐาน!B28>0,สมมติฐาน!B5/(MIN(สมมติฐาน!B32,สมมติฐาน!B34)*365*3+MAX(0,สมมติฐาน!B32-สมมติฐาน!B34)*365*3-สมมติฐาน!B28),999) -> 7.2293996 | C10: =IF(MIN(สมมติฐาน!B32,สมมติฐาน!B34)*365*3.5+MAX(0,สมมติฐาน!B32-สมมติฐาน!B34)*365*3-สมมติฐาน!B28>0,สมมติฐาน!B5/(MIN(สมมติฐาน!B32,สมมติฐาน!B34)*365*3.5+MAX(0,สมมติฐาน!B32-สมมติฐาน!B34)*365*3-สมมติฐาน!B28),999) -> 6.7118265 | D10: =IF(MIN(สมมติฐาน!B32,สมมติฐาน!B34)*365*4+MAX(0,สมมติฐาน!B32-สมมติฐาน!B34)*365*3-สมมติฐาน!B28>0,สมมติฐาน!B5/(MIN(สมมติฐาน!B32,สมมติฐาน!B34)*365*4+MAX(0,สมมติฐาน!B32-สมมติฐาน!B34)*365*3-สมมติฐาน!B28),999) -> 6.2634112 | E10: =IF(MIN(สมมติฐาน!B32,สมมติฐาน!B34)*365*4.5+MAX(0,สมมติฐาน!B32-สมมติฐาน!B34)*365*3-สมมติฐาน!B28>0,สมมติฐาน!B5/(MIN(สมมติฐาน!B32,สมมติฐาน!B34)*365*4.5+MAX(0,สมมติฐาน!B32-สมมติฐาน!B34)*365*3-สมมติฐาน!B28),999) -> 5.8711606 | F10: =IF(MIN(สมมติฐาน!B32,สมมติฐาน!B34)*365*5+MAX(0,สมมติฐาน!B32-สมมติฐาน!B34)*365*3-สมมติฐาน!B28>0,สมมติฐาน!B5/(MIN(สมมติฐาน!B32,สมมติฐาน!B34)*365*5+MAX(0,สมมติฐาน!B32-สมมติฐาน!B34)*365*3-สมมติฐาน!B28),999) -> 5.5251445 | G10: =IF(MIN(สมมติฐาน!B32,สมมติฐาน!B34)*365*5.5+MAX(0,สมมติฐาน!B32-สมมติฐาน!B34)*365*3-สมมติฐาน!B28>0,สมมติฐาน!B5/(MIN(สมมติฐาน!B32,สมมติฐาน!B34)*365*5.5+MAX(0,สมมติฐาน!B32-สมมติฐาน!B34)*365*3-สมมติฐาน!B28),999) -> 5.2176434 | H10: =IF(MIN(สมมติฐาน!B32,สมมติฐาน!B34)*365*6+MAX(0,สมมติฐาน!B32-สมมติฐาน!B34)*365*3-สมมติฐาน!B28>0,สมมติฐาน!B5/(MIN(สมมติฐาน!B32,สมมติฐาน!B34)*365*6+MAX(0,สมมติฐาน!B32-สมมติฐาน!B34)*365*3-สมมติฐาน!B28),999) -> 4.9425656
A11: 3.5 | B11: =IF(MIN(สมมติฐาน!B32,สมมติฐาน!B34)*365*3+MAX(0,สมมติฐาน!B32-สมมติฐาน!B34)*365*3.5-สมมติฐาน!B28>0,สมมติฐาน!B5/(MIN(สมมติฐาน!B32,สมมติฐาน!B34)*365*3+MAX(0,สมมติฐาน!B32-สมมติฐาน!B34)*365*3.5-สมมติฐาน!B28),999) -> 6.4502643 | C11: =IF(MIN(สมมติฐาน!B32,สมมติฐาน!B34)*365*3.5+MAX(0,สมมติฐาน!B32-สมมติฐาน!B34)*365*3.5-สมมติฐาน!B28>0,สมมติฐาน!B5/(MIN(สมมติฐาน!B32,สมมติฐาน!B34)*365*3.5+MAX(0,สมมติฐาน!B32-สมมติฐาน!B34)*365*3.5-สมมติฐาน!B28),999) -> 6.0350367 | D11: =IF(MIN(สมมติฐาน!B32,สมมติฐาน!B34)*365*4+MAX(0,สมมติฐาน!B32-สมมติฐาน!B34)*365*3.5-สมมติฐาน!B28>0,สมมติฐาน!B5/(MIN(สมมติฐาน!B32,สมมติฐาน!B34)*365*4+MAX(0,สมมติฐาน!B32-สมมติฐาน!B34)*365*3.5-สมมติฐาน!B28),999) -> 5.6700354 | E11: =IF(MIN(สมมติฐาน!B32,สมมติฐาน!B34)*365*4.5+MAX(0,สมมติฐาน!B32-สมมติฐาน!B34)*365*3.5-สมมติฐาน!B28>0,สมมติฐาน!B5/(MIN(สมมติฐาน!B32,สมมติฐาน!B34)*365*4.5+MAX(0,สมมติฐาน!B32-สมมติฐาน!B34)*365*3.5-สมมติฐาน!B28),999) -> 5.346667 | F11: =IF(MIN(สมมติฐาน!B32,สมมติฐาน!B34)*365*5+MAX(0,สมมติฐาน!B32-สมมติฐาน!B34)*365*3.5-สมมติฐาน!B28>0,สมมติฐาน!B5/(MIN(สมมติฐาน!B32,สมมติฐาน!B34)*365*5+MAX(0,สมมติฐาน!B32-สมมติฐาน!B34)*365*3.5-สมมติฐาน!B28),999) -> 5.0581926 | G11: =IF(MIN(สมมติฐาน!B32,สมมติฐาน!B34)*365*5.5+MAX(0,สมมติฐาน!B32-สมมติฐาน!B34)*365*3.5-สมมติฐาน!B28>0,สมมติฐาน!B5/(MIN(สมมติฐาน!B32,สมมติฐาน!B34)*365*5.5+MAX(0,สมมติฐาน!B32-สมมติฐาน!B34)*365*3.5-สมมติฐาน!B28),999) -> 4.7992534 | H11: =IF(MIN(สมมติฐาน!B32,สมมติฐาน!B34)*365*6+MAX(0,สมมติฐาน!B32-สมมติฐาน!B34)*365*3.5-สมมติฐาน!B28>0,สมมติฐาน!B5/(MIN(สมมติฐาน!B32,สมมติฐาน!B34)*365*6+MAX(0,สมมติฐาน!B32-สมมติฐาน!B34)*365*3.5-สมมติฐาน!B28),999) -> 4.5655344
A13: กรณี 2: มีแบต — Payback Period (ปี)
A14: FiT ↓ / ค่าไฟ → | B14: 3 | C14: 3.5 | D14: 4 | E14: 4.5 | F14: 5 | G14: 5.5 | H14: 6
A15: 1 | B15: =IF((MIN(สมมติฐาน!B32,สมมติฐาน!B34)+MIN(สมมติฐาน!B35,MIN(MAX(0,สมมติฐาน!B32-สมมติฐาน!B34),(สมมติฐาน!B12*สมมติฐาน!B14))*สมมติฐาน!B15))*365*3+MAX(0,MAX(0,สมมติฐาน!B32-สมมติฐาน!B34)-(สมมติฐาน!B12*สมมติฐาน!B14))*365*1-สมมติฐาน!B28>0,(สมมติฐาน!B5+สมมติฐาน!B13)/((MIN(สมมติฐาน!B32,สมมติฐาน!B34)+MIN(สมมติฐาน!B35,MIN(MAX(0,สมมติฐาน!B32-สมมติฐาน!B34),(สมมติฐาน!B12*สมมติฐาน!B14))*สมมติฐาน!B15))*365*3+MAX(0,MAX(0,สมมติฐาน!B32-สมมติฐาน!B34)-(สมมติฐาน!B12*สมมติฐาน!B14))*365*1-สมมติฐาน!B28),999) -> 13.931322 | C15: =IF((MIN(สมมติฐาน!B32,สมมติฐาน!B34)+MIN(สมมติฐาน!B35,MIN(MAX(0,สมมติฐาน!B32-สมมติฐาน!B34),(สมมติฐาน!B12*สมมติฐาน!B14))*สมมติฐาน!B15))*365*3.5+MAX(0,MAX(0,สมมติฐาน!B32-สมมติฐาน!B34)-(สมมติฐาน!B12*สมมติฐาน!B14))*365*1-สมมติฐาน!B28>0,(สมมติฐาน!B5+สมมติฐาน!B13)/((MIN(สมมติฐาน!B32,สมมติฐาน!B34)+MIN(สมมติฐาน!B35,MIN(MAX(0,สมมติฐาน!B32-สมมติฐาน!B34),(สมมติฐาน!B12*สมมติฐาน!B14))*สมมติฐาน!B15))*365*3.5+MAX(0,MAX(0,สมมติฐาน!B32-สมมติฐาน!B34)-(สมมติฐาน!B12*สมมติฐาน!B14))*365*1-สมมติฐาน!B28),999) -> 11.694984 | D15: =IF((MIN(สมมติฐาน!B32,สมมติฐาน!B34)+MIN(สมมติฐาน!B35,MIN(MAX(0,สมมติฐาน!B32-สมมติฐาน!B34),(สมมติฐาน!B12*สมมติฐาน!B14))*สมมติฐาน!B15))*365*4+MAX(0,MAX(0,สมมติฐาน!B32-สมมติฐาน!B34)-(สมมติฐาน!B12*สมมติฐาน!B14))*365*1-สมมติฐาน!B28>0,(สมมติฐาน!B5+สมมติฐาน!B13)/((MIN(สมมติฐาน!B32,สมมติฐาน!B34)+MIN(สมมติฐาน!B35,MIN(MAX(0,สมมติฐาน!B32-สมมติฐาน!B34),(สมมติฐาน!B12*สมมติฐาน!B14))*สมมติฐาน!B15))*365*4+MAX(0,MAX(0,สมมติฐาน!B32-สมมติฐาน!B34)-(สมมติฐาน!B12*สมมติฐาน!B14))*365*1-สมมติฐาน!B28),999) -> 10.077314 | E15: =IF((MIN(สมมติฐาน!B32,สมมติฐาน!B34)+MIN(สมมติฐาน!B35,MIN(MAX(0,สมมติฐาน!B32-สมมติฐาน!B34),(สมมติฐาน!B12*สมมติฐาน!B14))*สมมติฐาน!B15))*365*4.5+MAX(0,MAX(0,สมมติฐาน!B32-สมมติฐาน!B34)-(สมมติฐาน!B12*สมมติฐาน!B14))*365*1-สมมติฐาน!B28>0,(สมมติฐาน!B5+สมมติฐาน!B13)/((MIN(สมมติฐาน!B32,สมมติฐาน!B34)+MIN(สมมติฐาน!B35,MIN(MAX(0,สมมติฐาน!B32-สมมติฐาน!B34),(สมมติฐาน!B12*สมมติฐาน!B14))*สมมติฐาน!B15))*365*4.5+MAX(0,MAX(0,สมมติฐาน!B32-สมมติฐาน!B34)-(สมมติฐาน!B12*สมมติฐาน!B14))*365*1-สมมติฐาน!B28),999) -> 8.8527823 | F15: =IF((MIN(สมมติฐาน!B32,สมมติฐาน!B34)+MIN(สมมติฐาน!B35,MIN(MAX(0,สมมติฐาน!B32-สมมติฐาน!B34),(สมมติฐาน!B12*สมมติฐาน!B14))*สมมติฐาน!B15))*365*5+MAX(0,MAX(0,สมมติฐาน!B32-สมมติฐาน!B34)-(สมมติฐาน!B12*สมมติฐาน!B14))*365*1-สมมติฐาน!B28>0,(สมมติฐาน!B5+สมมติฐาน!B13)/((MIN(สมมติฐาน!B32,สมมติฐาน!B34)+MIN(สมมติฐาน!B35,MIN(MAX(0,สมมติฐาน!B32-สมมติฐาน!B34),(สมมติฐาน!B12*สมมติฐาน!B14))*สมมติฐาน!B15))*365*5+MAX(0,MAX(0,สมมติฐาน!B32-สมมติฐาน!B34)-(สมมติฐาน!B12*สมมติฐาน!B14))*365*1-สมมติฐาน!B28),999) -> 7.8936016 | G15: =IF((MIN(สมมติฐาน!B32,สมมติฐาน!B34)+MIN(สมมติฐาน!B35,MIN(MAX(0,สมมติฐาน!B32-สมมติฐาน!B34),(สมมติฐาน!B12*สมมติฐาน!B14))*สมมติฐาน!B15))*365*5.5+MAX(0,MAX(0,สมมติฐาน!B32-สมมติฐาน!B34)-(สมมติฐาน!B12*สมมติฐาน!B14))*365*1-สมมติฐาน!B28>0,(สมมติฐาน!B5+สมมติฐาน!B13)/((MIN(สมมติฐาน!B32,สมมติฐาน!B34)+MIN(สมมติฐาน!B35,MIN(MAX(0,สมมติฐาน!B32-สมมติฐาน!B34),(สมมติฐาน!B12*สมมติฐาน!B14))*สมมติฐาน!B15))*365*5.5+MAX(0,MAX(0,สมมติฐาน!B32-สมมติฐาน!B34)-(สมมติฐาน!B12*สมมติฐาน!B14))*365*1-สมมติฐาน!B28),999) -> 7.1219527 | H15: =IF((MIN(สมมติฐาน!B32,สมมติฐาน!B34)+MIN(สมมติฐาน!B35,MIN(MAX(0,สมมติฐาน!B32-สมมติฐาน!B34),(สมมติฐาน!B12*สมมติฐาน!B14))*สมมติฐาน!B15))*365*6+MAX(0,MAX(0,สมมติฐาน!B32-สมมติฐาน!B34)-(สมมติฐาน!B12*สมมติฐาน!B14))*365*1-สมมติฐาน!B28>0,(สมมติฐาน!B5+สมมติฐาน!B13)/((MIN(สมมติฐาน!B32,สมมติฐาน!B34)+MIN(สมมติฐาน!B35,MIN(MAX(0,สมมติฐาน!B32-สมมติฐาน!B34),(สมมติฐาน!B12*สมมติฐาน!B14))*สมมติฐาน!B15))*365*6+MAX(0,MAX(0,สมมติฐาน!B32-สมมติฐาน!B34)-(สมมติฐาน!B12*สมมติฐาน!B14))*365*1-สมมติฐาน!B28),999) -> 6.4877359
A16: 1.5 | B16: =IF((MIN(สมมติฐาน!B32,สมมติฐาน!B34)+MIN(สมมติฐาน!B35,MIN(MAX(0,สมมติฐาน!B32-สมมติฐาน!B34),(สมมติฐาน!B12*สมมติฐาน!B14))*สมมติฐาน!B15))*365*3+MAX(0,MAX(0,สมมติฐาน!B32-สมมติฐาน!B34)-(สมมติฐาน!B12*สมมติฐาน!B14))*365*1.5-สมมติฐาน!B28>0,(สมมติฐาน!B5+สมมติฐาน!B13)/((MIN(สมมติฐาน!B32,สมมติฐาน!B34)+MIN(สมมติฐาน!B35,MIN(MAX(0,สมมติฐาน!B32-สมมติฐาน!B34),(สมมติฐาน!B12*สมมติฐาน!B14))*สมมติฐาน!B15))*365*3+MAX(0,MAX(0,สมมติฐาน!B32-สมมติฐาน!B34)-(สมมติฐาน!B12*สมมติฐาน!B14))*365*1.5-สมมติฐาน!B28),999) -> 13.398999 | C16: =IF((MIN(สมมติฐาน!B32,สมมติฐาน!B34)+MIN(สมมติฐาน!B35,MIN(MAX(0,สมมติฐาน!B32-สมมติฐาน!B34),(สมมติฐาน!B12*สมมติฐาน!B14))*สมมติฐาน!B15))*365*3.5+MAX(0,MAX(0,สมมติฐาน!B32-สมมติฐาน!B34)-(สมมติฐาน!B12*สมมติฐาน!B14))*365*1.5-สมมติฐาน!B28>0,(สมมติฐาน!B5+สมมติฐาน!B13)/((MIN(สมมติฐาน!B32,สมมติฐาน!B34)+MIN(สมมติฐาน!B35,MIN(MAX(0,สมมติฐาน!B32-สมมติฐาน!B34),(สมมติฐาน!B12*สมมติฐาน!B14))*สมมติฐาน!B15))*365*3.5+MAX(0,MAX(0,สมมติฐาน!B32-สมมติฐาน!B34)-(สมมติฐาน!B12*สมมติฐาน!B14))*365*1.5-สมมติฐาน!B28),999) -> 11.317532 | D16: =IF((MIN(สมมติฐาน!B32,สมมติฐาน!B34)+MIN(สมมติฐาน!B35,MIN(MAX(0,สมมติฐาน!B32-สมมติฐาน!B34),(สมมติฐาน!B12*สมมติฐาน!B14))*สมมติฐาน!B15))*365*4+MAX(0,MAX(0,สมมติฐาน!B32-สมมติฐาน!B34)-(สมมติฐาน!B12*สมมติฐาน!B14))*365*1.5-สมมติฐาน!B28>0,(สมมติฐาน!B5+สมมติฐาน!B13)/((MIN(สมมติฐาน!B32,สมมติฐาน!B34)+MIN(สมมติฐาน!B35,MIN(MAX(0,สมมติฐาน!B32-สมมติฐาน!B34),(สมมติฐาน!B12*สมมติฐาน!B14))*สมมติฐาน!B15))*365*4+MAX(0,MAX(0,สมมติฐาน!B32-สมมติฐาน!B34)-(สมมติฐาน!B12*สมมติฐาน!B14))*365*1.5-สมมติฐาน!B28),999) -> 9.7958031 | E16: =IF((MIN(สมมติฐาน!B32,สมมติฐาน!B34)+MIN(สมมติฐาน!B35,MIN(MAX(0,สมมติฐาน!B32-สมมติฐาน!B34),(สมมติฐาน!B12*สมมติฐาน!B14))*สมมติฐาน!B15))*365*4.5+MAX(0,MAX(0,สมมติฐาน!B32-สมมติฐาน!B34)-(สมมติฐาน!B12*สมมติฐาน!B14))*365*1.5-สมมติฐาน!B28>0,(สมมติฐาน!B5+สมมติฐาน!B13)/((MIN(สมมติฐาน!B32,สมมติฐาน!B34)+MIN(สมมติฐาน!B35,MIN(MAX(0,สมมติฐาน!B32-สมมติฐาน!B34),(สมมติฐาน!B12*สมมติฐาน!B14))*สมมติฐาน!B15))*365*4.5+MAX(0,MAX(0,สมมติฐาน!B32-สมมติฐาน!B34)-(สมมติฐาน!B12*สมมติฐาน!B14))*365*1.5-สมมติฐาน!B28),999) -> 8.6347896 | F16: =IF((MIN(สมมติฐาน!B32,สมมติฐาน!B34)+MIN(สมมติฐาน!B35,MIN(MAX(0,สมมติฐาน!B32-สมมติฐาน!B34),(สมมติฐาน!B12*สมมติฐาน!B14))*สมมติฐาน!B15))*365*5+MAX(0,MAX(0,สมมติฐาน!B32-สมมติฐาน!B34)-(สมมติฐาน!B12*สมมติฐาน!B14))*365*1.5-สมมติฐาน!B28>0,(สมมติฐาน!B5+สมมติฐาน!B13)/((MIN(สมมติฐาน!B32,สมมติฐาน!B34)+MIN(สมมติฐาน!B35,MIN(MAX(0,สมมติฐาน!B32-สมมติฐาน!B34),(สมมติฐาน!B12*สมมติฐาน!B14))*สมมติฐาน!B15))*365*5+MAX(0,MAX(0,สมมติฐาน!B32-สมมติฐาน!B34)-(สมมติฐาน!B12*สมมติฐาน!B14))*365*1.5-สมมติฐาน!B28),999) -> 7.7198242 | G16: =IF((MIN(สมมติฐาน!B32,สมมติฐาน!B34)+MIN(สมมติฐาน!B35,MIN(MAX(0,สมมติฐาน!B32-สมมติฐาน!B34),(สมมติฐาน!B12*สมมติฐาน!B14))*สมมติฐาน!B15))*365*5.5+MAX(0,MAX(0,สมมติฐาน!B32-สมมติฐาน!B34)-(สมมติฐาน!B12*สมมติฐาน!B14))*365*1.5-สมมติฐาน!B28>0,(สมมติฐาน!B5+สมมติฐาน!B13)/((MIN(สมมติฐาน!B32,สมมติฐาน!B34)+MIN(สมมติฐาน!B35,MIN(MAX(0,สมมติฐาน!B32-สมมติฐาน!B34),(สมมติฐาน!B12*สมมติฐาน!B14))*สมมติฐาน!B15))*365*5.5+MAX(0,MAX(0,สมมติฐาน!B32-สมมติฐาน!B34)-(สมมติฐาน!B12*สมมติฐาน!B14))*365*1.5-สมมติฐาน!B28),999) -> 6.9801852 | H16: =IF((MIN(สมมติฐาน!B32,สมมติฐาน!B34)+MIN(สมมติฐาน!B35,MIN(MAX(0,สมมติฐาน!B32-สมมติฐาน!B34),(สมมติฐาน!B12*สมมติฐาน!B14))*สมมติฐาน!B15))*365*6+MAX(0,MAX(0,สมมติฐาน!B32-สมมติฐาน!B34)-(สมมติฐาน!B12*สมมติฐาน!B14))*365*1.5-สมมติฐาน!B28>0,(สมมติฐาน!B5+สมมติฐาน!B13)/((MIN(สมมติฐาน!B32,สมมติฐาน!B34)+MIN(สมมติฐาน!B35,MIN(MAX(0,สมมติฐาน!B32-สมมติฐาน!B34),(สมมติฐาน!B12*สมมติฐาน!B14))*สมมติฐาน!B15))*365*6+MAX(0,MAX(0,สมมติฐาน!B32-สมมติฐาน!B34)-(สมมติฐาน!B12*สมมติฐาน!B14))*365*1.5-สมมติฐาน!B28),999) -> 6.3698844
